Workbook
Name calcMETHOD: ראשי!$C$40
Name inputFUEL: ראשי!$F$48
Name InternalWeight: נתונים!$S$17
Name maxallowFUEL: נתונים!$S$12
Name maxallowFUEL2250: נתונים!$S$15
Name MAXGROSS: ברזל!$I$35
Name maxPWRspare: ראשי!$L$38
Name OGE: 'מה"ק'!$G$17
Name ogeCALC: נתונים!$AK$3
Name OGEtable: 'מה"ק'!$F$5:$L$13
Name regCALC: נתונים!$AK$2
Name takeoffWT: נתונים!$S$5
Name takoffweight: ראשי!$F$49
Name userBAMBI: ראשי!$D$19
Name userBASKET: ראשי!$D$15
Name userBASKETkg: ראשי!$H$15
Name userCARGO: ראשי!$D$17
Name userCARGOkg: ראשי!$H$17
Name userCHAIRS: ראשי!$D$21
Name userCONFIG: ראשי!$D$9
Name userFLIR: ראשי!$D$11
Name userWATERkg: ראשי!$D$47
Name userXP: ראשי!$D$13
Name WeightOnCable: 'מה"ק'!$I$21
Name wtWITHOUTFuel: נתונים!$C$49:$H$52
Name zerofuelWT: נתונים!$S$4
Name דלק: נתונים!$AH$2:$AH$76
Name מרכז_כובד_אורכי: נתונים!$W$9:$X$13
Name מרכז_כובד_רוחבי: נתונים!$Z$9:$AA$18

Sheet ראשי
A1: Check Point Threat Extraction Secured This Document | J1: Get Original
D4: גרסה | E4: 3.5
B6: מסוק | D6: BMK
B9: תצורת כסאות | D9: 11: POLICE/FIRE + 2
B11: מערכת | D11: SHAPO
B13: XP | D13: כן | F13: =IF(AND(OR('משקל מערכות'!$B$27:$B$29),userXP="לא"),"שים לב - תצורה זו אינה מאושרת ללא XP ","")
B15: סל כיבוי | D15: לא | F15: משקל בסל
B17: מתלה מטען + מראות | D17: כן | F17: משקל על הוו
B19: במבי | D19: ללא | F19: =IF(AND(userBAMBI="מחובר",userCARGO="לא"),"יש לבחור מתלה מטען + מראות",IF(AND(userBAMBI="מחובר",calcMETHOD=regCALC,OR('משקל מערכות'!$B$32:$B$39)),"EXT CARGO לבמבי במצב מחובר יש לבחור 'חישוב לביצוע'",IF(AND(userBAMBI="בסל",userBASKET="לא"),"לבמבי בסל יש לבחור 'סל כיבוי - כן'",IF(AND(calcMETHOD=regCALC,userBAMBI="ללא",userCARGO="כן",userCARGOkg>0),"EXT CARGO למטען על הוו יש לבחור 'חישוב לביצוע'",""))))
B21: כסאות | D21: 3
B25: צוות | D25: טייס ימין | H25: טייס שמאל
D26: 80 | H26: 80
J27: פירוט תצורה
D28: 3 | F28: 2 | H28: 1 | J28: =IF(COUNT(נתונים!$I$33:$I$44)=0,"ללא",COUNT(נתונים!$I$33:$I$44))&" כסאות" -> 2 כסאות
J29: ="מערכת - "&IF(NOT(OR('משקל מערכות'!$B$27:$B$29,'משקל מערכות'!$B$36:$B$39)),"ללא",userFLIR) -> מערכת - SHAPO
B30: תא נוסעים | D30: 13 | F30: 12 | H30: 11 | J30: ="XP - "&IF(NOT(OR('משקל מערכות'!$B$27:$B$29,'משקל מערכות'!$B$36:$B$39)),"לא",userXP) -> XP - כן
J31: ="סל כיבוי - "&IF(NOT(OR('משקל מערכות'!$B$32:$B$39)),"לא",userBASKET) -> סל כיבוי - לא
D32: 14 | J32: ="מתלה/מטען מראות - "&IF((OR('משקל מערכות'!$B$32:$B$38)),"כן",IF('משקל מערכות'!$B$39,userCARGO,"לא")) -> מתלה/מטען מראות - כן
J33: ="במבי - "&IF(NOT(OR('משקל מערכות'!$B$32:$B$39)),"ללא",userBAMBI) -> במבי - ללא
D35: משקל | F35: LONG | H35: LAT
B36: ציוד נוסף | C36: 1)
C38: גובה | D38: 2000 | F38: טמפ' | G38: 20 | I38: חישוב מקסימום כח לפי | L38: מה''ק מינוס 80KG
I39: =IF(AND(calcMETHOD=ogeCALC,maxPWRspare="מה''ק (ללא ספייר)"),"טיסה עם מטען חיצוני מאושרת למה''ק מינוס 80 בלבד","")
C40: חישוב להמראה ונחיתה (2370) | H40: =IF(AND($C$40=ogeCALC,OR('משקל מערכות'!$B$27:$B$31),NOT('משקל מערכות'!B39)),"יש לוודא תצורה עם מתלה מטען ","")
C42: מסוק ריק | F42: =VLOOKUP($D$6,נתונים!C6:D9,2,FALSE) -> 1605.6 | J42: פריסטים לגיחה
C43: תצורה והתקנות | F43: =SUM(נתונים!$L$6:$L$19)+SUM(נתונים!$D$33:$D$44) -> 86.3 | H43: מסוק וצוות | J43: מים | L43: דלק
C44: ברזל | F44: =ROUND(SUM(F42:F43),0) -> 1692 | H44: =ROUND(SUM($F$44:$F$45),0)&" kg" -> 1852 kg | J44: 70% (476 ל') | L44: =IF(ROUND(OGE-SUM($F$44:$F$46)-0.7*680-40,0)>59,ROUND(OGE-SUM($F$44:$F$46)-0.7*680-40,0)&" kg","----") -> 292 kg
C45: צוות | F45: =SUM(נתונים!$D$14:$D$15) -> 160 | I45: + | J45: 80% (544 ל') | L45: =IF(ROUND(OGE-SUM($F$44:$F$46)-0.8*680-40,0)>59,ROUND(OGE-SUM($F$44:$F$46)-0.8*680-40,0)&" kg","----") -> 224 kg
C46: נוסעים וציוד | F46: =SUM(נתונים!$D$19:$D$27,נתונים!$L$30:$L$33) -> 0 | H46: משקל מועיל | J46: 90% (612 ל') | L46: =IF(ROUND(OGE-SUM($F$44:$F$46)-0.9*680-40,0)>59,ROUND(OGE-SUM($F$44:$F$46)-0.9*680-40,0)&" kg","----") -> 156 kg
C47: =IF(userBAMBI="מחובר","במבי + מים","מטען חיצוני") -> מטען חיצוני | D47: 0 | F47: =IF(AND(OR('משקל מערכות'!$B$32:$B$39),calcMETHOD=ogeCALC),IF(userBAMBI="מחובר",נתונים!$L$25,IF(userCARGO="כן",userCARGOkg,0)),0) -> 0 | H47: =ROUND(IF(AND($C$40=ogeCALC,OR('משקל מערכות'!$B$32:$B$39)),OGE,MAXGROSS)-SUM($F$44:$F$45),0)&" kg" -> 518 kg | J47: 100% (680 ל') | L47: =IF(ROUND(OGE-SUM($F$44:$F$46)-680-40,0)>59,ROUND(OGE-SUM($F$44:$F$46)-680-40,0)&" kg","----") -> 88 kg
C48: דלק | D48: ="(מירבי "&maxallowFUEL&")" -> (מירבי 426) | F48: 400
C49: משקל בהמראה | E49: kg | F49: =SUM($F$44:$F$48) -> 2252 | H49: =IF(AND(calcMETHOD=ogeCALC,OR('משקל מערכות'!$B$32:$B$39)),OGE,MAXGROSS)&" kg" -> 2370 kg
C50: משקל פנימי | D50: ="(מירבי "&maxallowFUEL2250&")" -> (מירבי 398) | E50: kg | F50: =InternalWeight -> 2252
C51: =IF(AND(InternalWeight>2250,WeightOnCable),"INTERNAL WEIGHT OVER 2250KG","")
C52: =IF(נתונים!$X$5=TRUE,"AFT CG LIMIT OUT OF RANGE",IF(נתונים!$W$5=TRUE,"FWD CG LIMIT OUT OF RANGE","CG LIMIT WITHIN RANGE")) -> CG LIMIT WITHIN RANGE

Sheet נתונים
AD1: במבי | AE1: מערכת | AF1: זרקור | AG1: משקל | AH1: דלק | AI1: מים (%) | AJ1: משקל מירבי | AK1: סוג חישוב | AL1: חישוב מה"ק
S2: ACTUAL FUEL TABLE | AD2: מחובר | AE2: ללא | AF2: לא | AG2: 0 | AH2: 0 | AI2: 0 | AJ2: 2370 | AK2: חישוב להמראה ונחיתה (2370) | AL2: מה''ק מינוס 80KG
S3: MASS | T3: LONG ARM | U3: LAT ARM | W3: LONG CG EXEED | AD3: בסל | AE3: SHAPO | AF3: כן | AG3: 5 | AH3: 1 | AI3: 0.7 | AK3: חישוב לביצוע EXT CARGO | AL3: מה''ק (ללא ספייר)
C4: EMPTY WEIGHT | K4: REMOVABLE EQUIPMENT | R4: משקל ללא דלק | S4: =VLOOKUP(ראשי!$D$4,נתונים!$C$49:$H$52,2,FALSE) -> 1851.9 | T4: =VLOOKUP(ראשי!$D$4,wtWITHOUTFuel,3,FALSE) -> 3.3516918 | U4: =VLOOKUP(ראשי!$D$4,wtWITHOUTFuel,6,FALSE) -> 0.0015142286 | W4: FWD | X4: AFT | AD4: בבטן | AE4: DSP | AG4: 10 | AH4: 2 | AI4: 0.8
C5: מסוק | D5: משקל | E5: LONG ARM | F5: מומנט אורכי | G5: מומנט רוחבי | H5: LAT ARM | K5: ציוד | L5: משקל | M5: LONG ARM | N5: מומנט אורכי | O5: מומנט רוחבי | P5: LAT ARM | R5: משקל עם דלק | S5: =$S$4+inputFUEL -> 2251.9 | T5: =($S$4*$T$4+inputFUEL*$T$9)/($S$4+inputFUEL) -> 3.3744829 | U5: =($S$4*$U$4+inputFUEL*$U$9)/($S$4+inputFUEL) -> 0.0012452596 | W5: =IF(AND(ראשי!$C$38=ogeCALC,OR('משקל מערכות'!$B$32:$B$39)),$S5>($W$34*$T$5+$X$34),$S5>($W$19*$T$5+$X$19)) -> FALSE | X5: =IF(AND(ראשי!$C$38=ogeCALC,OR('משקל מערכות'!$B$32:$B$39)),$S5>($W$35*$T$5+$X$35),$S5>($W$20*$T$5+$X$20)) -> FALSE | AD5: ללא | AG5: 15 | AH5: 3 | AI5: 0.9
C6: BMK | D6: =ברזל!I4 -> 1605.6 | E6: =ברזל!J4 -> 3.54 | F6: =D6*E6 -> 5683.824 | G6: =D6*H6 -> 11.2392 | H6: =ברזל!M4 -> 0.007 | K6: =IF('משקל מערכות'!$B4=0,"",'משקל מערכות'!C4) | L6: =IF('משקל מערכות'!$B4=0,"",'משקל מערכות'!D4) | M6: =IF('משקל מערכות'!$B4=0,"",'משקל מערכות'!E4) | N6: =IF('משקל מערכות'!$B4=0,"",'משקל מערכות'!F4) | O6: =IF('משקל מערכות'!$B4=0,"",'משקל מערכות'!G4) | P6: =IF('משקל מערכות'!$B4=0,"",'משקל מערכות'!H4) | AG6: 20 | AH6: 4 | AI6: 1
C7: BML | D7: =ברזל!I5 -> 1609.5 | E7: =ברזל!J5 -> 3.5 | F7: =D7*E7 -> 5633.25 | G7: =D7*H7 -> -16.095 | H7: =ברזל!M5 -> -0.01 | K7: =IF('משקל מערכות'!$B5=0,"",'משקל מערכות'!C5) | L7: =IF('משקל מערכות'!$B5=0,"",'משקל מערכות'!D5) | M7: =IF('משקל מערכות'!$B5=0,"",'משקל מערכות'!E5) | N7: =IF('משקל מערכות'!$B5=0,"",'משקל מערכות'!F5) | O7: =IF('משקל מערכות'!$B5=0,"",'משקל מערכות'!G5) | P7: =IF('משקל מערכות'!$B5=0,"",'משקל מערכות'!H5) | S7: CONSTANT FUEL DATA | W7: LONG CG ENV | Z7: LAT CG ENV | AG7: 25 | AH7: 5
C8: BMM | D8: =ברזל!I6 -> 1610.8 | E8: =ברזל!J6 -> 3.52 | F8: =D8*E8 -> 5670.016 | G8: =D8*H8 -> -16.108 | H8: =ברזל!M6 -> -0.01 | K8: =IF('משקל מערכות'!$B6=0,"",'משקל מערכות'!C6) | L8: =IF('משקל מערכות'!$B6=0,"",'משקל מערכות'!D6) | M8: =IF('משקל מערכות'!$B6=0,"",'משקל מערכות'!E6) | N8: =IF('משקל מערכות'!$B6=0,"",'משקל מערכות'!F6) | O8: =IF('משקל מערכות'!$B6=0,"",'משקל מערכות'!G6) | P8: =IF('משקל מערכות'!$B6=0,"",'משקל מערכות'!H6) | T8: LONG ARM | U8: LAT ARM | W8: מומנט | X8: משקל | Z8: מומנט | AA8: משקל | AG8: 30 | AH8: 6
C9: BMN | D9: =ברזל!I7 -> 1613.1 | E9: =ברזל!J7 -> 3.52 | F9: =D9*E9 -> 5678.112 | G9: =D9*H9 -> -16.131 | H9: =ברזל!M7 -> -0.01 | K9: =IF('משקל מערכות'!$B7=0,"",'משקל מערכות'!C7) -> CONTROP IMAGER SHAPO | L9: =IF('משקל מערכות'!$B7=0,"",'משקל מערכות'!D7) -> 18 | M9: =IF('משקל מערכות'!$B7=0,"",'משקל מערכות'!E7) -> 1.03 | N9: =IF('משקל מערכות'!$B7=0,"",'משקל מערכות'!F7) -> 18.54 | O9: =IF('משקל מערכות'!$B7=0,"",'משקל מערכות'!G7) -> -9.54 | P9: =IF('משקל מערכות'!$B7=0,"",'משקל מערכות'!H7) -> -0.53 | T9: 3.48 | U9: 0 | W9: 3.23 | X9: 2370 | Z9: -0.08 | AA9: 2370 | AG9: 35 | AH9: 7
K10: =IF('משקל מערכות'!$B8=0,"",'משקל מערכות'!C8) | L10: =IF('משקל מערכות'!$B8=0,"",'משקל מערכות'!D8) | M10: =IF('משקל מערכות'!$B8=0,"",'משקל מערכות'!E8) | N10: =IF('משקל מערכות'!$B8=0,"",'משקל מערכות'!F8) | O10: =IF('משקל מערכות'!$B8=0,"",'משקל מערכות'!G8) | P10: =IF('משקל מערכות'!$B8=0,"",'משקל מערכות'!H8) | W10: 3.407 | X10: 2370 | Z10: 0.08 | AA10: 2370 | AG10: 40 | AH10: 8
K11: =IF('משקל מערכות'!$B9=0,"",'משקל מערכות'!C9) -> Nightsun XP Search Light | L11: =IF('משקל מערכות'!$B9=0,"",'משקל מערכות'!D9) -> 33 | M11: =IF('משקל מערכות'!$B9=0,"",'משקל מערכות'!E9) -> 4.83 | N11: =IF('משקל מערכות'!$B9=0,"",'משקל מערכות'!F9) -> 159.39 | O11: =IF('משקל מערכות'!$B9=0,"",'משקל מערכות'!G9) -> 0 | P11: =IF('משקל מערכות'!$B9=0,"",'משקל מערכות'!H9) -> 0 | S11: MAX ALLOWED FUEL (TOTAL) | W11: 3.49 | X11: 1750 | Z11: 0.08 | AA11: 2250 | AG11: 45 | AH11: 9
C12: CREW | K12: =IF('משקל מערכות'!$B10=0,"",'משקל מערכות'!C10) | L12: =IF('משקל מערכות'!$B10=0,"",'משקל מערכות'!D10) | M12: =IF('משקל מערכות'!$B10=0,"",'משקל מערכות'!E10) | N12: =IF('משקל מערכות'!$B10=0,"",'משקל מערכות'!F10) | O12: =IF('משקל מערכות'!$B10=0,"",'משקל מערכות'!G10) | P12: =IF('משקל מערכות'!$B10=0,"",'משקל מערכות'!H10) | S12: =IF(AND(calcMETHOD=ogeCALC,OR('משקל מערכות'!$B$32:$B$39)),IF(ROUND(OGE-zerofuelWT,0)>426,426,ROUND(OGE-zerofuelWT,0)),IF(ROUND(MAXGROSS-zerofuelWT,0)>426,426,ROUND(MAXGROSS-zerofuelWT,0))) -> 426 | W12: 3.498 | X12: 1310 | Z12: 0.14 | AA12: 2250 | AG12: 50 | AH12: 10
C13: ציוד | D13: משקל | E13: LONG ARM | F13: מומנט אורכי | G13: מומנט רוחבי | H13: LAT ARM | K13: =IF('משקל מערכות'!$B11=0,"",'משקל מערכות'!C11) | L13: =IF('משקל מערכות'!$B11=0,"",'משקל מערכות'!D11) | M13: =IF('משקל מערכות'!$B11=0,"",'משקל מערכות'!E11) | N13: =IF('משקל מערכות'!$B11=0,"",'משקל מערכות'!F11) | O13: =IF('משקל מערכות'!$B11=0,"",'משקל מערכות'!G11) | P13: =IF('משקל מערכות'!$B11=0,"",'משקל מערכות'!H11) | W13: 3.17 | X13: 1310 | Z13: 0.14 | AA13: 1300 | AG13: 55 | AH13: 11
C14: טייס ימין | D14: =ראשי!D24 -> 80 | E14: 1.55 | F14: =D14*E14 -> 124 | G14: =D14*H14 -> 28.8 | H14: 0.36 | K14: =IF('משקל מערכות'!$B12=0,"",'משקל מערכות'!C12) | L14: =IF('משקל מערכות'!$B12=0,"",'משקל מערכות'!D12) | M14: =IF('משקל מערכות'!$B12=0,"",'משקל מערכות'!E12) | N14: =IF('משקל מערכות'!$B12=0,"",'משקל מערכות'!F12) | O14: =IF('משקל מערכות'!$B12=0,"",'משקל מערכות'!G12) | P14: =IF('משקל מערכות'!$B12=0,"",'משקל מערכות'!H12) | S14: MAX ALLOWED FUEL (INT 2250) | W14: 3.17 | X14: 2000 | Z14: -0.18 | AA14: 1300 | AG14: 60 | AH14: 12
C15: טייס שמאל | D15: =ראשי!H24 -> 80 | E15: 1.55 | F15: =D15*E15 -> 124 | G15: =D15*H15 -> -28.8 | H15: -0.36 | K15: =IF('משקל מערכות'!$B13=0,"",'משקל מערכות'!C13) | L15: =IF('משקל מערכות'!$B13=0,"",'משקל מערכות'!D13) | M15: =IF('משקל מערכות'!$B13=0,"",'משקל מערכות'!E13) | N15: =IF('משקל מערכות'!$B13=0,"",'משקל מערכות'!F13) | O15: =IF('משקל מערכות'!$B13=0,"",'משקל מערכות'!G13) | P15: =IF('משקל מערכות'!$B13=0,"",'משקל מערכות'!H13) | S15: =2250-(InternalWeight-inputFUEL) -> 398 | W15: 3.23 | X15: 2370 | Z15: -0.18 | AA15: 2250 | AG15: 65 | AH15: 13
K16: =IF('משקל מערכות'!$B14=0,"",'משקל מערכות'!C14) -> CARGO HOOK DOUBLE DET PROVISIONS | L16: =IF('משקל מערכות'!$B14=0,"",'משקל מערכות'!D14) -> 13.6 | M16: =IF('משקל מערכות'!$B14=0,"",'משקל מערכות'!E14) -> 3.38 | N16: =IF('משקל מערכות'!$B14=0,"",'משקל מערכות'!F14) -> 45.968 | O16: =IF('משקל מערכות'!$B14=0,"",'משקל מערכות'!G14) -> 0 | P16: =IF('משקל מערכות'!$B14=0,"",'משקל מערכות'!H14) -> 0 | Z16: -0.08 | AA16: 2250 | AG16: 70 | AH16: 14
C17: PASSENGERS | K17: =IF('משקל מערכות'!$B15=0,"",'משקל מערכות'!C15) -> CARGO HOOK MIRROR DETACHABLE PARTS | L17: =IF('משקל מערכות'!$B15=0,"",'משקל מערכות'!D15) -> 1.7 | M17: =IF('משקל מערכות'!$B15=0,"",'משקל מערכות'!E15) -> 0.28 | N17: =IF('משקל מערכות'!$B15=0,"",'משקל מערכות'!F15) -> 0.476 | O17: =IF('משקל מערכות'!$B15=0,"",'משקל מערכות'!G15) -> 1.105 | P17: =IF('משקל מערכות'!$B15=0,"",'משקל מערכות'!H15) -> 0.65 | S17: =SUM(ראשי!F42,ראשי!F43,ראשי!F44,ראשי!F46) -> 2252 | T17: INTERNAL WEIGHT | V17: INT LONG CG LIMIT GRAPH | Z17: -0.08 | AA17: 2370 | AG17: 75 | AH17: 15
C18: כסא | D18: משקל | E18: LONG ARM | F18: מומנט אורכי | G18: מומנט רוחבי | H18: LAT ARM | I18: קוד תצורה | W18: a | X18: b | AG18: 80 | AH18: 16
C19: 1 | D19: =IF(E19="","",ראשי!H27) -> 0 | E19: =IFERROR(INDEX($E$33:$H$44,MATCH($C19,$I$33:$I$44,0),1),"") -> 2.54 | F19: =IF(E19<>"",D19*E19,"") -> 0 | G19: =IF(E19<>"",D19*H19,"") -> 0 | H19: =IFERROR(INDEX($E$33:$H$44,MATCH($C19,$I$33:$I$44,0),4),"") -> -0.62 | V19: FWD | W19: =SLOPE(נתונים!X14:X15,נתונים!W14:W15) -> 6166.6667 | X19: =X14-W14*W19 -> -17548.333 | AG19: 85 | AH19: 17
C20: 2 | D20: =IF(E20="","",ראשי!F27) | E20: =IFERROR(INDEX($E$33:$H$44,MATCH($C20,$I$33:$I$44,0),1),"") | F20: =IF(E20<>"",D20*E20,"") | G20: =IF(E20<>"",D20*H20,"") | H20: =IFERROR(INDEX($E$33:$H$44,MATCH($C20,$I$33:$I$44,0),4),"") | V20: AFT | W20: =SLOPE(X10:X11,W10:W11) -> -7469.8795 | X20: =X11-W11*W20 -> 27819.88 | AG20: 90 | AH20: 18
C21: 3 | D21: =IF(E21="","",ראשי!D27) -> 0 | E21: =IFERROR(INDEX($E$33:$H$44,MATCH($C21,$I$33:$I$44,0),1),"") -> 2.54 | F21: =IF(E21<>"",D21*E21,"") -> 0 | G21: =IF(E21<>"",D21*H21,"") -> 0 | H21: =IFERROR(INDEX($E$33:$H$44,MATCH($C21,$I$33:$I$44,0),4),"") -> 0.62 | K21: EXTERNAL LOAD | V21: FUEL | W21: =SLOPE($S$4:$S$5,$T$4:$T$5) -> 17550.707 | X21: =$S$5-$T$5*$W$21 -> -56972.659 | AG21: 95 | AH21: 19
C22: 11 | D22: =IF(E22="","",ראשי!H29) | E22: =IFERROR(INDEX($E$33:$H$44,MATCH($C22,$I$33:$I$44,0),1),"") | F22: =IF(E22<>"",D22*E22,"") | G22: =IF(E22<>"",D22*H22,"") | H22: =IFERROR(INDEX($E$33:$H$44,MATCH($C22,$I$33:$I$44,0),4),"") | K22: ציוד | L22: משקל | M22: LONG ARM | N22: מומנט אורכי | O22: מומנט רוחבי | P22: LAT ARM | AG22: 100 | AH22: 20
C23: 12 | D23: =IF(E23="","",ראשי!F29) | E23: =IFERROR(INDEX($E$33:$H$44,MATCH($C23,$I$33:$I$44,0),1),"") | F23: =IF(E23<>"",D23*E23,"") | G23: =IF(E23<>"",D23*H23,"") | H23: =IFERROR(INDEX($E$33:$H$44,MATCH($C23,$I$33:$I$44,0),4),"") | K23: =IF('משקל מערכות'!$B16=0,"",'משקל מערכות'!C16) -> CARGO WEIGHT ON HOOK | L23: =IF('משקל מערכות'!$B16=0,"",'משקל מערכות'!D16) -> 0 | M23: =IF('משקל מערכות'!$B16=0,"",'משקל מערכות'!E16) -> 3.38 | N23: =IF('משקל מערכות'!$B16=0,"",'משקל מערכות'!F16) -> 0 | O23: =IF('משקל מערכות'!$B16=0,"",'משקל מערכות'!G16) -> 0 | P23: =IF('משקל מערכות'!$B16=0,"",'משקל מערכות'!H16) -> 0 | T23: CALC EXT CG ENV | W23: EXT LON CG ENV | Z23: EXT LAT CG ENV | AG23: 105 | AH23: 21
C24: 13 | D24: =IF(E24="","",ראשי!D29) | E24: =IFERROR(INDEX($E$33:$H$44,MATCH($C24,$I$33:$I$44,0),1),"") | F24: =IF(E24<>"",D24*E24,"") | G24: =IF(E24<>"",D24*H24,"") | H24: =IFERROR(INDEX($E$33:$H$44,MATCH($C24,$I$33:$I$44,0),4),"") | K24: =IF('משקל מערכות'!$B17=0,"",'משקל מערכות'!C17) | L24: =IF('משקל מערכות'!$B17=0,"",'משקל מערכות'!D17) | M24: =IF('משקל מערכות'!$B17=0,"",'משקל מערכות'!E17) | N24: =IF('משקל מערכות'!$B17=0,"",'משקל מערכות'!F17) | O24: =IF('משקל מערכות'!$B17=0,"",'משקל מערכות'!G17) | P24: =IF('משקל מערכות'!$B17=0,"",'משקל מערכות'!H17) | T24: מומנט | U24: משקל | W24: מומנט | X24: משקל | Z24: מומנט | AA24: משקל | AG24: 110 | AH24: 22
C25: 14 | D25: =IF(E25="","",ראשי!D31) | E25: =IFERROR(INDEX($E$33:$H$44,MATCH($C25,$I$33:$I$44,0),1),"") | F25: =IF(E25<>"",D25*E25,"") | G25: =IF(E25<>"",D25*H25,"") | H25: =IFERROR(INDEX($E$33:$H$44,MATCH($C25,$I$33:$I$44,0),4),"") | K25: =IF('משקל מערכות'!$B18=0,"",'משקל מערכות'!C18) | L25: =IF('משקל מערכות'!$B18=0,"",'משקל מערכות'!D18) | M25: =IF('משקל מערכות'!$B18=0,"",'משקל מערכות'!E18) | N25: =IF('משקל מערכות'!$B18=0,"",'משקל מערכות'!F18) | O25: =IF('משקל מערכות'!$B18=0,"",'משקל מערכות'!G18) | P25: =IF('משקל מערכות'!$B18=0,"",'משקל מערכות'!H18) | T25: ='מה"ק'!F23 -> 3.269 | U25: ='מה"ק'!G23 -> 2660 | W25: 3.29 | X25: 2800 | Z25: -0.08 | AA25: 2370 | AG25: 115 | AH25: 23
T26: ='מה"ק'!F24 -> 3.4358255 | U26: ='מה"ק'!G24 -> 2660 | W26: 3.43 | X26: 2800 | Z26: -0.08 | AA26: =OGE -> 2660 | AG26: 120 | AH26: 24
T27: =W27 -> 3.492 | U27: =X27 -> 1310 | W27: 3.492 | X27: 1310 | Z27: 0.08 | AA27: =OGE -> 2660 | AG27: 125 | AH27: 25
K28: MANUALLY ADDED EQUIPMENT | T28: =W28 -> 3.17 | U28: =X28 -> 1310 | W28: 3.17 | X28: 1310 | Z28: 0.08 | AA28: 2370 | AG28: 130 | AH28: 26
C29: תצורת כסאות | D29: =ראשי!$D$7 -> 11: POLICE/FIRE + 2 | K29: ציוד | L29: משקל | M29: LONG ARM | N29: מומנט אורכי | O29: מומנט רוחבי | P29: LAT ARM | T29: =W29 -> 3.17 | U29: =X29 -> 2000 | W29: 3.17 | X29: 2000 | AG29: 135 | AH29: 27
L30: =IF(M30="","",ראשי!D34) | M30: =IF(ראשי!F34="","",ראשי!F34) | N30: =IF(M30<>"",L30*M30,"") | O30: =IF(P30<>"",L30*P30,"") | P30: =IF(ראשי!H34="","",ראשי!H34) | T30: =T25 -> 3.269 | U30: =U25 -> 2660 | W30: 3.29 | X30: 2800 | AG30: 140 | AH30: 28
C31: SEAT CONFIGURATION | AG31: 145 | AH31: 29
C32: ציוד | D32: משקל | E32: LONG ARM | F32: מומנט אורכי | G32: מומנט רוחבי | H32: LAT ARM | I32: כסא | V32: EXT LONG CG LIMIT GRAPH | AG32: 150 | AH32: 30
C33: =IF(INDIRECT("תצורות!A"&(LEFT($D$29,2)-1)*13+ROW(A3))=0,"",INDIRECT("תצורות!A"&(LEFT($D$29,2)-1)*13+ROW(A3))) -> כסא נוסע שמאל קיצוני | D33: =IF(INDIRECT("תצורות!A"&(LEFT($D$29,2)-1)*13+ROW(A3))=0,"",INDIRECT("תצורות!b"&(LEFT($D$29,2)-1)*13+ROW(A3))) -> 10 | E33: =IF(INDIRECT("תצורות!A"&(LEFT($D$29,2)-1)*13+ROW(A3))=0,"",INDIRECT("תצורות!c"&(LEFT($D$29,2)-1)*13+ROW(A3))) -> 2.54 | F33: =IF(D33<>"",D33*E33,"") -> 25.4 | G33: =IF(D33<>"",D33*H33,"") -> -6.2 | H33: =IF(INDIRECT("תצורות!A"&(LEFT($D$29,2)-1)*13+ROW(A3))=0,"",INDIRECT("תצורות!d"&(LEFT($D$29,2)-1)*13+ROW(A3))) -> -0.62 | I33: =IF(INDIRECT("תצורות!A"&(LEFT($D$29,2)-1)*13+ROW(B3))="","",INT(INDIRECT("תצורות!E"&(LEFT($D$29,2)-1)*13+ROW(B3)))) -> 1 | W33: a | X33: b | AG33: 155 | AH33: 31
C34: =IF(INDIRECT("תצורות!A"&(LEFT($D$29,2)-1)*13+ROW(A4))=0,"",INDIRECT("תצורות!A"&(LEFT($D$29,2)-1)*13+ROW(A4))) -> כסא נוסע ימין קיצוני | D34: =IF(INDIRECT("תצורות!A"&(LEFT($D$29,2)-1)*13+ROW(A4))=0,"",INDIRECT("תצורות!b"&(LEFT($D$29,2)-1)*13+ROW(A4))) -> 10 | E34: =IF(INDIRECT("תצורות!A"&(LEFT($D$29,2)-1)*13+ROW(A4))=0,"",INDIRECT("תצורות!c"&(LEFT($D$29,2)-1)*13+ROW(A4))) -> 2.54 | F34: =IF(D34<>"",D34*E34,"") -> 25.4 | G34: =IF(D34<>"",D34*H34,"") -> 6.2 | H34: =IF(INDIRECT("תצורות!A"&(LEFT($D$29,2)-1)*13+ROW(A4))=0,"",INDIRECT("תצורות!d"&(LEFT($D$29,2)-1)*13+ROW(A4))) -> 0.62 | I34: =IF(INDIRECT("תצורות!A"&(LEFT($D$29,2)-1)*13+ROW(B4))="","",INT(INDIRECT("תצורות!E"&(LEFT($D$29,2)-1)*13+ROW(B4)))) -> 3 | V34: FWD | W34: =SLOPE(נתונים!X29:X30,נתונים!W29:W30) -> 6666.6667 | X34: =X29-W29*W34 -> -19133.333 | AG34: 160 | AH34: 32
C35: =IF(INDIRECT("תצורות!A"&(LEFT($D$29,2)-1)*13+ROW(A5))=0,"",INDIRECT("תצורות!A"&(LEFT($D$29,2)-1)*13+ROW(A5))) | D35: =IF(INDIRECT("תצורות!A"&(LEFT($D$29,2)-1)*13+ROW(A5))=0,"",INDIRECT("תצורות!b"&(LEFT($D$29,2)-1)*13+ROW(A5))) | E35: =IF(INDIRECT("תצורות!A"&(LEFT($D$29,2)-1)*13+ROW(A5))=0,"",INDIRECT("תצורות!c"&(LEFT($D$29,2)-1)*13+ROW(A5))) | F35: =IF(D35<>"",D35*E35,"") | G35: =IF(D35<>"",D35*H35,"") | H35: =IF(INDIRECT("תצורות!A"&(LEFT($D$29,2)-1)*13+ROW(A5))=0,"",INDIRECT("תצורות!d"&(LEFT($D$29,2)-1)*13+ROW(A5))) | I35: =IF(INDIRECT("תצורות!A"&(LEFT($D$29,2)-1)*13+ROW(B5))="","",INT(INDIRECT("תצורות!E"&(LEFT($D$29,2)-1)*13+ROW(B5)))) | V35: AFT | W35: =SLOPE(X26:X27,W26:W27) -> -24032.258 | X35: =X26-W26*W35 -> 85230.645 | AG35: 165 | AH35: 33
C36: =IF(INDIRECT("תצורות!A"&(LEFT($D$29,2)-1)*13+ROW(A6))=0,"",INDIRECT("תצורות!A"&(LEFT($D$29,2)-1)*13+ROW(A6))) | D36: =IF(INDIRECT("תצורות!A"&(LEFT($D$29,2)-1)*13+ROW(A6))=0,"",INDIRECT("תצורות!b"&(LEFT($D$29,2)-1)*13+ROW(A6))) | E36: =IF(INDIRECT("תצורות!A"&(LEFT($D$29,2)-1)*13+ROW(A6))=0,"",INDIRECT("תצורות!c"&(LEFT($D$29,2)-1)*13+ROW(A6))) | F36: =IF(D36<>"",D36*E36,"") | G36: =IF(D36<>"",D36*H36,"") | H36: =IF(INDIRECT("תצורות!A"&(LEFT($D$29,2)-1)*13+ROW(A6))=0,"",INDIRECT("תצורות!d"&(LEFT($D$29,2)-1)*13+ROW(A6))) | I36: =IF(INDIRECT("תצורות!A"&(LEFT($D$29,2)-1)*13+ROW(B6))="","",INT(INDIRECT("תצורות!E"&(LEFT($D$29,2)-1)*13+ROW(B6)))) | V36: FUEL | W36: =SLOPE($S$4:$S$5,$T$4:$T$5) -> 17550.707 | X36: =$S$5-$T$5*$W$21 -> -56972.659 | AG36: 170 | AH36: 34
C37: =IF(INDIRECT("תצורות!A"&(LEFT($D$29,2)-1)*13+ROW(A7))=0,"",INDIRECT("תצורות!A"&(LEFT($D$29,2)-1)*13+ROW(A7))) | D37: =IF(INDIRECT("תצורות!A"&(LEFT($D$29,2)-1)*13+ROW(A7))=0,"",INDIRECT("תצורות!b"&(LEFT($D$29,2)-1)*13+ROW(A7))) | E37: =IF(INDIRECT("תצורות!A"&(LEFT($D$29,2)-1)*13+ROW(A7))=0,"",INDIRECT("תצורות!c"&(LEFT($D$29,2)-1)*13+ROW(A7))) | F37: =IF(D37<>"",D37*E37,"") | G37: =IF(D37<>"",D37*H37,"") | H37: =IF(INDIRECT("תצורות!A"&(LEFT($D$29,2)-1)*13+ROW(A7))=0,"",INDIRECT("תצורות!d"&(LEFT($D$29,2)-1)*13+ROW(A7))) | I37: =IF(INDIRECT("תצורות!A"&(LEFT($D$29,2)-1)*13+ROW(B7))="","",INT(INDIRECT("תצורות!E"&(LEFT($D$29,2)-1)*13+ROW(B7)))) | AG37: 175 | AH37: 35
C38: =IF(INDIRECT("תצורות!A"&(LEFT($D$29,2)-1)*13+ROW(A8))=0,"",INDIRECT("תצורות!A"&(LEFT($D$29,2)-1)*13+ROW(A8))) | D38: =IF(INDIRECT("תצורות!A"&(LEFT($D$29,2)-1)*13+ROW(A8))=0,"",INDIRECT("תצורות!b"&(LEFT($D$29,2)-1)*13+ROW(A8))) | E38: =IF(INDIRECT("תצורות!A"&(LEFT($D$29,2)-1)*13+ROW(A8))=0,"",INDIRECT("תצורות!c"&(LEFT($D$29,2)-1)*13+ROW(A8))) | F38: =IF(D38<>"",D38*E38,"") | G38: =IF(D38<>"",D38*H38,"") | H38: =IF(INDIRECT("תצורות!A"&(LEFT($D$29,2)-1)*13+ROW(A8))=0,"",INDIRECT("תצורות!d"&(LEFT($D$29,2)-1)*13+ROW(A8))) | I38: =IF(INDIRECT("תצורות!A"&(LEFT($D$29,2)-1)*13+ROW(B8))="","",INT(INDIRECT("תצורות!E"&(LEFT($D$29,2)-1)*13+ROW(B8)))) | AG38: 180 | AH38: 36
C39: =IF(INDIRECT("תצורות!A"&(LEFT($D$29,2)-1)*13+ROW(A9))=0,"",INDIRECT("תצורות!A"&(LEFT($D$29,2)-1)*13+ROW(A9))) | D39: =IF(INDIRECT("תצורות!A"&(LEFT($D$29,2)-1)*13+ROW(A9))=0,"",INDIRECT("תצורות!b"&(LEFT($D$29,2)-1)*13+ROW(A9))) | E39: =IF(INDIRECT("תצורות!A"&(LEFT($D$29,2)-1)*13+ROW(A9))=0,"",INDIRECT("תצורות!c"&(LEFT($D$29,2)-1)*13+ROW(A9))) | F39: =IF(D39<>"",D39*E39,"") | G39: =IF(D39<>"",D39*H39,"") | H39: =IF(INDIRECT("תצורות!A"&(LEFT($D$29,2)-1)*13+ROW(A9))=0,"",INDIRECT("תצורות!d"&(LEFT($D$29,2)-1)*13+ROW(A9))) | I39: =IF(INDIRECT("תצורות!A"&(LEFT($D$29,2)-1)*13+ROW(B9))="","",INT(INDIRECT("תצורות!E"&(LEFT($D$29,2)-1)*13+ROW(B9)))) | AG39: 185 | AH39: 37
C40: =IF(INDIRECT("תצורות!A"&(LEFT($D$29,2)-1)*13+ROW(A10))=0,"",INDIRECT("תצורות!A"&(LEFT($D$29,2)-1)*13+ROW(A10))) | D40: =IF(INDIRECT("תצורות!A"&(LEFT($D$29,2)-1)*13+ROW(A10))=0,"",INDIRECT("תצורות!b"&(LEFT($D$29,2)-1)*13+ROW(A10))) | E40: =IF(INDIRECT("תצורות!A"&(LEFT($D$29,2)-1)*13+ROW(A10))=0,"",INDIRECT("תצורות!c"&(LEFT($D$29,2)-1)*13+ROW(A10))) | F40: =IF(D40<>"",D40*E40,"") | G40: =IF(D40<>"",D40*H40,"") | H40: =IF(INDIRECT("תצורות!A"&(LEFT($D$29,2)-1)*13+ROW(A10))=0,"",INDIRECT("תצורות!d"&(LEFT($D$29,2)-1)*13+ROW(A10))) | I40: =IF(INDIRECT("תצורות!A"&(LEFT($D$29,2)-1)*13+ROW(B10))="","",INT(INDIRECT("תצורות!E"&(LEFT($D$29,2)-1)*13+ROW(B10)))) | AG40: 190 | AH40: 38
...

Sheet תצורות
A1: Description | B1: KG | C1: LONG ARM | D1: LAT ARM | N1: טבלת קוד תצורת כסאות
A2: POLICE + 1 | E2: זיהוי כסא | N2: קוד | O2: LONG ARM | P2: LAT ARM
A3: כסא נוסע שמאל קיצוני | B3: 10 | C3: 2.54 | D3: -0.62 | E3: 1 | N3: {=INDEX($E$3:$E$200,MATCH(0,COUNTIF($N$1:N1,$E$3:$E$200),0))} -> 1 | O3: =IFERROR((INDEX($C$3:$D$200,MATCH($N3,$E$3:$E$200,0),1)),"") -> 2.54 | P3: =IFERROR((INDEX($C$3:$D$200,MATCH($N3,$E$3:$E$200,0),2)),"") -> -0.62
N4: {=INDEX($E$3:$E$200,MATCH(0,COUNTIF($N$1:N3,$E$3:$E$200),0))} -> 0 | O4: =IFERROR((INDEX($C$3:$D$200,MATCH($N4,$E$3:$E$200,0),1)),"") | P4: =IFERROR((INDEX($C$3:$D$200,MATCH($N4,$E$3:$E$200,0),2)),"")
N5: {=INDEX($E$3:$E$200,MATCH(0,COUNTIF($N$1:N4,$E$3:$E$200),0))} -> 3 | O5: =IFERROR((INDEX($C$3:$D$200,MATCH($N5,$E$3:$E$200,0),1)),"") -> 2.54 | P5: =IFERROR((INDEX($C$3:$D$200,MATCH($N5,$E$3:$E$200,0),2)),"") -> 0.62
N6: {=INDEX($E$3:$E$200,MATCH(0,COUNTIF($N$1:N5,$E$3:$E$200),0))} -> 2 | O6: =IFERROR((INDEX($C$3:$D$200,MATCH($N6,$E$3:$E$200,0),1)),"") -> 2.54 | P6: =IFERROR((INDEX($C$3:$D$200,MATCH($N6,$E$3:$E$200,0),2)),"") -> 0
N7: {=INDEX($E$3:$E$200,MATCH(0,COUNTIF($N$1:N6,$E$3:$E$200),0))} -> 11 | O7: =IFERROR((INDEX($C$3:$D$200,MATCH($N7,$E$3:$E$200,0),1)),"") -> 2.54 | P7: =IFERROR((INDEX($C$3:$D$200,MATCH($N7,$E$3:$E$200,0),2)),"") -> -0.62
N8: {=INDEX($E$3:$E$200,MATCH(0,COUNTIF($N$1:N7,$E$3:$E$200),0))} -> 14 | O8: =IFERROR((INDEX($C$3:$D$200,MATCH($N8,$E$3:$E$200,0),1)),"") -> 2.54 | P8: =IFERROR((INDEX($C$3:$D$200,MATCH($N8,$E$3:$E$200,0),2)),"") -> 0.62
N9: {=INDEX($E$3:$E$200,MATCH(0,COUNTIF($N$1:N8,$E$3:$E$200),0))} -> 13 | O9: =IFERROR((INDEX($C$3:$D$200,MATCH($N9,$E$3:$E$200,0),1)),"") -> 2.54 | P9: =IFERROR((INDEX($C$3:$D$200,MATCH($N9,$E$3:$E$200,0),2)),"") -> 0.38
N10: {=INDEX($E$3:$E$200,MATCH(0,COUNTIF($N$1:N9,$E$3:$E$200),0))} -> 12 | O10: =IFERROR((INDEX($C$3:$D$200,MATCH($N10,$E$3:$E$200,0),1)),"") -> 2.54 | P10: =IFERROR((INDEX($C$3:$D$200,MATCH($N10,$E$3:$E$200,0),2)),"") -> -0.38
N11: {=INDEX($E$3:$E$200,MATCH(0,COUNTIF($N$1:N10,$E$3:$E$200),0))} | O11: =IFERROR((INDEX($C$3:$D$200,MATCH($N11,$E$3:$E$200,0),1)),"") | P11: =IFERROR((INDEX($C$3:$D$200,MATCH($N11,$E$3:$E$200,0),2)),"")
O12: =IFERROR((INDEX($C$3:$D$200,MATCH($N12,$E$3:$E$200,0),1)),"") | P12: =IFERROR((INDEX($C$3:$D$200,MATCH($N12,$E$3:$E$200,0),2)),"")
O13: =IFERROR((INDEX($C$3:$D$200,MATCH($N13,$E$3:$E$200,0),1)),"") | P13: =IFERROR((INDEX($C$3:$D$200,MATCH($N13,$E$3:$E$200,0),2)),"")
O14: =IFERROR((INDEX($C$3:$D$200,MATCH($N14,$E$3:$E$200,0),1)),"") | P14: =IFERROR((INDEX($C$3:$D$200,MATCH($N14,$E$3:$E$200,0),2)),"")
A15: POLICE + 2 | O15: =IFERROR((INDEX($C$3:$D$200,MATCH($N15,$E$3:$E$200,0),1)),"") | P15: =IFERROR((INDEX($C$3:$D$200,MATCH($N15,$E$3:$E$200,0),2)),"")
A16: כסא נוסע שמאל קיצוני | B16: 10 | C16: 2.54 | D16: -0.62 | E16: 1 | O16: =IFERROR((INDEX($C$3:$D$200,MATCH($N16,$E$3:$E$200,0),1)),"") | P16: =IFERROR((INDEX($C$3:$D$200,MATCH($N16,$E$3:$E$200,0),2)),"")
A17: כסא נוסע ימין קיצוני | B17: 10 | C17: 2.54 | D17: 0.62 | E17: 3 | O17: =IFERROR((INDEX($C$3:$D$200,MATCH($N17,$E$3:$E$200,0),1)),"") | P17: =IFERROR((INDEX($C$3:$D$200,MATCH($N17,$E$3:$E$200,0),2)),"")
O18: =IFERROR((INDEX($C$3:$D$200,MATCH($N18,$E$3:$E$200,0),1)),"") | P18: =IFERROR((INDEX($C$3:$D$200,MATCH($N18,$E$3:$E$200,0),2)),"")
O19: =IFERROR((INDEX($C$3:$D$200,MATCH($N19,$E$3:$E$200,0),1)),"") | P19: =IFERROR((INDEX($C$3:$D$200,MATCH($N19,$E$3:$E$200,0),2)),"")
O20: =IFERROR((INDEX($C$3:$D$200,MATCH($N20,$E$3:$E$200,0),1)),"") | P20: =IFERROR((INDEX($C$3:$D$200,MATCH($N20,$E$3:$E$200,0),2)),"")
O21: =IFERROR((INDEX($C$3:$D$200,MATCH($N21,$E$3:$E$200,0),1)),"") | P21: =IFERROR((INDEX($C$3:$D$200,MATCH($N21,$E$3:$E$200,0),2)),"")
O22: =IFERROR((INDEX($C$3:$D$200,MATCH($N22,$E$3:$E$200,0),1)),"") | P22: =IFERROR((INDEX($C$3:$D$200,MATCH($N22,$E$3:$E$200,0),2)),"")
O23: =IFERROR((INDEX($C$3:$D$200,MATCH($N23,$E$3:$E$200,0),1)),"") | P23: =IFERROR((INDEX($C$3:$D$200,MATCH($N23,$E$3:$E$200,0),2)),"")
O24: =IFERROR((INDEX($C$3:$D$200,MATCH($N24,$E$3:$E$200,0),1)),"") | P24: =IFERROR((INDEX($C$3:$D$200,MATCH($N24,$E$3:$E$200,0),2)),"")
O25: =IFERROR((INDEX($C$3:$D$200,MATCH($N25,$E$3:$E$200,0),1)),"") | P25: =IFERROR((INDEX($C$3:$D$200,MATCH($N25,$E$3:$E$200,0),2)),"")
O26: =IFERROR((INDEX($C$3:$D$200,MATCH($N26,$E$3:$E$200,0),1)),"") | P26: =IFERROR((INDEX($C$3:$D$200,MATCH($N26,$E$3:$E$200,0),2)),"")
O27: =IFERROR((INDEX($C$3:$D$200,MATCH($N27,$E$3:$E$200,0),1)),"") | P27: =IFERROR((INDEX($C$3:$D$200,MATCH($N27,$E$3:$E$200,0),2)),"")
A28: POLICE + 3 | O28: =IFERROR((INDEX($C$3:$D$200,MATCH($N28,$E$3:$E$200,0),1)),"") | P28: =IFERROR((INDEX($C$3:$D$200,MATCH($N28,$E$3:$E$200,0),2)),"")
A29: כסא נוסע שמאל קיצוני | B29: 10 | C29: 2.54 | D29: -0.62 | E29: 1 | O29: =IFERROR((INDEX($C$3:$D$200,MATCH($N29,$E$3:$E$200,0),1)),"") | P29: =IFERROR((INDEX($C$3:$D$200,MATCH($N29,$E$3:$E$200,0),2)),"")
A30: כסא נוסע ימין קיצוני | B30: 10 | C30: 2.54 | D30: 0.62 | E30: 3 | O30: =IFERROR((INDEX($C$3:$D$200,MATCH($N30,$E$3:$E$200,0),1)),"") | P30: =IFERROR((INDEX($C$3:$D$200,MATCH($N30,$E$3:$E$200,0),2)),"")
A31: כסא נוסע מרכזי | B31: 10 | C31: 2.54 | D31: 0 | E31: 2 | O31: =IFERROR((INDEX($C$3:$D$200,MATCH($N31,$E$3:$E$200,0),1)),"") | P31: =IFERROR((INDEX($C$3:$D$200,MATCH($N31,$E$3:$E$200,0),2)),"")
O32: =IFERROR((INDEX($C$3:$D$200,MATCH($N32,$E$3:$E$200,0),1)),"") | P32: =IFERROR((INDEX($C$3:$D$200,MATCH($N32,$E$3:$E$200,0),2)),"")
O33: =IFERROR((INDEX($C$3:$D$200,MATCH($N33,$E$3:$E$200,0),1)),"") | P33: =IFERROR((INDEX($C$3:$D$200,MATCH($N33,$E$3:$E$200,0),2)),"")
O34: =IFERROR((INDEX($C$3:$D$200,MATCH($N34,$E$3:$E$200,0),1)),"") | P34: =IFERROR((INDEX($C$3:$D$200,MATCH($N34,$E$3:$E$200,0),2)),"")
O35: =IFERROR((INDEX($C$3:$D$200,MATCH($N35,$E$3:$E$200,0),1)),"") | P35: =IFERROR((INDEX($C$3:$D$200,MATCH($N35,$E$3:$E$200,0),2)),"")
O36: =IFERROR((INDEX($C$3:$D$200,MATCH($N36,$E$3:$E$200,0),1)),"") | P36: =IFERROR((INDEX($C$3:$D$200,MATCH($N36,$E$3:$E$200,0),2)),"")
O37: =IFERROR((INDEX($C$3:$D$200,MATCH($N37,$E$3:$E$200,0),1)),"") | P37: =IFERROR((INDEX($C$3:$D$200,MATCH($N37,$E$3:$E$200,0),2)),"")
O38: =IFERROR((INDEX($C$3:$D$200,MATCH($N38,$E$3:$E$200,0),1)),"") | P38: =IFERROR((INDEX($C$3:$D$200,MATCH($N38,$E$3:$E$200,0),2)),"")
O39: =IFERROR((INDEX($C$3:$D$200,MATCH($N39,$E$3:$E$200,0),1)),"") | P39: =IFERROR((INDEX($C$3:$D$200,MATCH($N39,$E$3:$E$200,0),2)),"")
A41: TRANSPORT + 3
...

Sheet ברזל
D2: מקרא | G2: שקילה | O2: Aircraft weighed full of Oils, empty of Fuel, 3 Flight Manuals, Pilots Blue Flight Log, Dual Flight Controls, Cargo Hook Removed,
D3: ניתן לעריכה | G3: מסוק | H3: תאריך | I3: משקל | J3: LONG ARM | K3: מומנט אורכי | L3: מומנט רוחבי | M3: LAT ARM | O3: 2 Mid Fwd Club Passenger Seats, 3 Aft Fwd Club Passenger Seats, Traffic Flight Officer Station (Stowed), Controp DSP-HD Camera,
D4: נתון מאסטר | G4: BMK | H4: 44629 | I4: 1605.6 | J4: 3.54 | K4: =I4*J4 -> 5683.824 | L4: =I4*M4 -> 11.2392 | M4: 0.007 | O4: Nightsun XP Search Light, Controp and Nightsun Hand Controller, PA Speakers, LH & RH Skid deflectors removed.
G5: BML | H5: 44628 | I5: 1609.5 | J5: 3.5 | M5: -0.01 | O5: No Headsets, No ICS Patch cords, No Fly Away Gear or Loose Equipment installed at this time. See equipment list section of Flight
G6: BMM | H6: 44637 | I6: 1610.8 | J6: 3.52 | M6: -0.01
G7: BMN | H7: 44637 | I7: 1613.1 | J7: 3.52 | M7: -0.01
D9: הפחתת ציוד
D10: ציוד | I10: משקל | J10: LONG ARM | K10: מומנט אורכי | L10: מומנט רוחבי | M10: LAT ARM
D11: LHS Mid Fwd Club Passenger Seat | I11: 12.36 | J11: 4190 | K11: =IFERROR(I11*J11,"") -> 51788.4 | L11: =IFERROR(I11*M11,"") -> -5932.8 | M11: -480
D12: RHS Mid Fwd Club Passenger Seat | I12: 12.36 | J12: 4190 | K12: =IFERROR(I12*J12,"") -> 51788.4 | L12: =IFERROR(I12*M12,"") -> 5932.8 | M12: 480
D13: LHS Aft Fwd Club Passenger Seat | I13: 12.38 | J13: 5060 | K13: =IFERROR(I13*J13,"") -> 62642.8 | L13: =IFERROR(I13*M13,"") -> -5694.8 | M13: -460
D14: MID Aft Fwd Club Passenger Seat | I14: 10.02 | J14: 5060 | K14: =IFERROR(I14*J14,"") -> 50701.2 | L14: =IFERROR(I14*M14,"") -> 0 | M14: 0
D15: RHS Aft Fwd Club Passenger Seat | I15: 12.38 | J15: 5060 | K15: =IFERROR(I15*J15,"") -> 62642.8 | L15: =IFERROR(I15*M15,"") -> 5694.8 | M15: 460
D16: Traffic Flight Officer Station (Stowed) | I16: =IFERROR(VLOOKUP($D16,'משקל מערכות'!$C$4:$H$18,2,FALSE),"") | J16: =IFERROR(VLOOKUP($D16,'משקל מערכות'!$C$4:$H$18,3,FALSE),"") | K16: =IFERROR(I16*J16,"") | L16: =IFERROR(I16*M16,"") | M16: =IFERROR(VLOOKUP($D16,'משקל מערכות'!$C$4:$H$18,6,FALSE),"")
D17: Controp DSP-HD Camera | I17: =IFERROR(VLOOKUP($D17,'משקל מערכות'!$C$4:$H$18,2,FALSE),"") -> 31.3 | J17: =IFERROR(VLOOKUP($D17,'משקל מערכות'!$C$4:$H$18,3,FALSE),"") -> 1.03 | K17: =IFERROR(I17*J17,"") -> 32.239 | L17: =IFERROR(I17*M17,"") -> -16.589 | M17: =IFERROR(VLOOKUP($D17,'משקל מערכות'!$C$4:$H$18,6,FALSE),"") -> -0.53
D18: Controp Hand Controller | I18: =IFERROR(VLOOKUP($D18,'משקל מערכות'!$C$4:$H$18,2,FALSE),"") | J18: =IFERROR(VLOOKUP($D18,'משקל מערכות'!$C$4:$H$18,3,FALSE),"") | K18: =IFERROR(I18*J18,"") | L18: =IFERROR(I18*M18,"") | M18: =IFERROR(VLOOKUP($D18,'משקל מערכות'!$C$4:$H$18,6,FALSE),"")
D19: Nightsun XP Search Light | I19: =IFERROR(VLOOKUP($D19,'משקל מערכות'!$C$4:$H$18,2,FALSE),"") -> 33 | J19: =IFERROR(VLOOKUP($D19,'משקל מערכות'!$C$4:$H$18,3,FALSE),"") -> 4.83 | K19: =IFERROR(I19*J19,"") -> 159.39 | L19: =IFERROR(I19*M19,"") -> 0 | M19: =IFERROR(VLOOKUP($D19,'משקל מערכות'!$C$4:$H$18,6,FALSE),"") -> 0
D20: Nightsun Hand Controller | I20: =IFERROR(VLOOKUP($D20,'משקל מערכות'!$C$4:$H$18,2,FALSE),"") | J20: =IFERROR(VLOOKUP($D20,'משקל מערכות'!$C$4:$H$18,3,FALSE),"") | K20: =IFERROR(I20*J20,"") | L20: =IFERROR(I20*M20,"") | M20: =IFERROR(VLOOKUP($D20,'משקל מערכות'!$C$4:$H$18,6,FALSE),"")
D21: PA Speakers | I21: =IFERROR(VLOOKUP($D21,'משקל מערכות'!$C$4:$H$18,2,FALSE),"") | J21: =IFERROR(VLOOKUP($D21,'משקל מערכות'!$C$4:$H$18,3,FALSE),"") | K21: =IFERROR(I21*J21,"") | L21: =IFERROR(I21*M21,"") | M21: =IFERROR(VLOOKUP($D21,'משקל מערכות'!$C$4:$H$18,6,FALSE),"")
I22: =IFERROR(VLOOKUP($D22,'משקל מערכות'!$C$4:$H$18,2,FALSE),"") | J22: =IFERROR(VLOOKUP($D22,'משקל מערכות'!$C$4:$H$18,3,FALSE),"") | K22: =IFERROR(I22*J22,"") | L22: =IFERROR(I22*M22,"") | M22: =IFERROR(VLOOKUP($D22,'משקל מערכות'!$C$4:$H$18,6,FALSE),"")
I23: =IFERROR(VLOOKUP($D23,'משקל מערכות'!$C$4:$H$18,2,FALSE),"") | J23: =IFERROR(VLOOKUP($D23,'משקל מערכות'!$C$4:$H$18,3,FALSE),"") | K23: =IFERROR(I23*J23,"") | L23: =IFERROR(I23*M23,"") | M23: =IFERROR(VLOOKUP($D23,'משקל מערכות'!$C$4:$H$18,6,FALSE),"")
I24: =IFERROR(VLOOKUP($D24,'משקל מערכות'!$C$4:$H$18,2,FALSE),"") | J24: =IFERROR(VLOOKUP($D24,'משקל מערכות'!$C$4:$H$18,3,FALSE),"") | K24: =IFERROR(I24*J24,"") | L24: =IFERROR(I24*M24,"") | M24: =IFERROR(VLOOKUP($D24,'משקל מערכות'!$C$4:$H$18,6,FALSE),"")
G35: משקל מירבי להמראה | I35: 2370

Sheet משקל מערכות
B3: כמות | C3: תאור | D3: KG | E3: LONG ARM | F3: מומנט אורכי | G3: מומנט רוחבי | H3: LAT ARM
B6: =IF(OR($B$27:$B$29,$B$36:$B$39),IF(userFLIR="DSP",1,0),0) -> 0 | C6: Controp DSP-HD Camera | D6: 31.3 | E6: 1.03 | F6: =D6*E6 -> 32.239 | G6: =D6*H6 -> -16.589 | H6: -0.53
B7: =IF(OR($B$27:$B$29,$B$36:$B$39),IF(userFLIR="SHAPO",1,0),0) -> 1 | C7: CONTROP IMAGER SHAPO | D7: 18 | E7: 1.03 | F7: =D7*E7 -> 18.54 | G7: =D7*H7 -> -9.54 | H7: -0.53
B9: =IF(OR($B$27:$B$29,$B$36:$B$39),IF(userXP="כן",1,0),0) -> 1 | C9: Nightsun XP Search Light | D9: 33 | E9: 4.83 | F9: =D9*E9 -> 159.39 | G9: =D9*H9 -> 0 | H9: 0
B10: =IF(OR($B$32:$B$39),IF(userBAMBI="בבטן",1,0),0) -> 0 | C10: BAMBI BUCKET IN CABIN | D10: 40 | E10: 2.25 | F10: =D10*E10 -> 90 | G10: =D10*H10 -> 0 | H10: 0
B11: =IF(OR($B$32:$B$39),IF(userBAMBI="בסל",1,0),0) -> 0 | C11: BAMBI BUCKET IN BASKET | D11: 40 | E11: 3.43 | F11: =D11*E11 -> 137.2 | G11: =D11*H11 -> -50 | H11: -1.25
B12: =IF(OR($B$32:$B$39),IF(userBASKET="כן",1,0),0) -> 0 | C12: SIDE BASKET | D12: 30.6 | E12: 3.43 | F12: =D12*E12 -> 104.958 | G12: =D12*H12 -> -38.25 | H12: -1.25
B13: =IF(OR($B$32:$B$39),IF(userBASKET="כן",1,0),0) -> 0 | C13: SIDE BASKET CARGO | D13: =userBASKETkg -> 0 | E13: 3.43 | F13: =D13*E13 -> 0 | G13: =D13*H13 -> 0 | H13: -1.25
B14: =IF(OR($B$32:$B$39),IF(userCARGO="כן",1,0),0) -> 1 | C14: CARGO HOOK DOUBLE DET PROVISIONS | D14: 13.6 | E14: 3.38 | F14: =D14*E14 -> 45.968 | G14: =D14*H14 -> 0 | H14: 0
B15: =IF(OR($B$32:$B$39),IF(userCARGO="כן",1,0),0) -> 1 | C15: CARGO HOOK MIRROR DETACHABLE PARTS | D15: 1.7 | E15: 0.28 | F15: =D15*E15 -> 0.476 | G15: =D15*H15 -> 1.105 | H15: 0.65
B16: =IF(AND(OR($B$32:$B$39),NOT(userBAMBI="מחובר"),userCARGO="כן"),1,0) -> 1 | C16: CARGO WEIGHT ON HOOK | D16: =IF(ראשי!$C$38=ogeCALC,userCARGOkg,0) -> 0 | E16: 3.38 | F16: =D16*E16 -> 0 | G16: =D16*H16 -> 0 | H16: 0
B18: =IF(AND(OR($B$32:$B$39),userBAMBI="מחובר"),1,0) -> 0 | C18: BAMBI WITH WATER | D18: =IF(ראשי!$C$38=ogeCALC,userWATERkg*680+40,0) -> 0 | E18: 3.38 | F18: =D18*E18 -> 0 | G18: =D18*H18 -> 0 | H18: 0
C25: CONFIGURATION LIST
B27: =ראשי!$D$7='משקל מערכות'!C27 -> FALSE | C27: 01: POLICE + 1
B28: =ראשי!$D$7='משקל מערכות'!C28 -> FALSE | C28: 02: POLICE + 2
B29: =ראשי!$D$7='משקל מערכות'!C29 -> FALSE | C29: 03: POLICE + 3
B30: =ראשי!$D$7='משקל מערכות'!C30 -> FALSE | C30: 04: TRANSPORT + 3
B31: =ראשי!$D$7='משקל מערכות'!C31 -> FALSE | C31: 05: TRANSPORT + 4
B32: =ראשי!$D$7='משקל מערכות'!C32 -> FALSE | C32: 06: FIRE - NO SEATS
B33: =ראשי!$D$7='משקל מערכות'!C33 -> FALSE | C33: 07: FIRE + 1
B34: =ראשי!$D$7='משקל מערכות'!C34 -> FALSE | C34: 08: FIRE + 2
B35: =ראשי!$D$7='משקל מערכות'!C35 -> FALSE | C35: 09: FIRE + 3
B36: =ראשי!$D$7='משקל מערכות'!C36 -> FALSE | C36: 10: POLICE/FIRE + 1
B37: =ראשי!$D$7='משקל מערכות'!C37 -> TRUE | C37: 11: POLICE/FIRE + 2
B38: =ראשי!$D$7='משקל מערכות'!C38 -> FALSE | C38: 12: POLICE/FIRE + 3
B39: =ראשי!$D$7='משקל מערכות'!C39 -> FALSE | C39: 13: CUSTOM

Sheet מה"ק
V1: גובה | W1: טמפ | X1: מהק 80
V2: 0 | W2: 0 | X2: כן
V3: 100 | W3: 1 | X3: לא
F4: 10 | G4: 15 | H4: 20 | I4: 25 | J4: 30 | K4: 35 | L4: 40 | V4: 200 | W4: 2
E5: 0 | F5: 2800 | G5: 2800 | H5: 2800 | I5: 2785 | J5: 2775 | K5: 2765 | L5: 2750 | V5: 300 | W5: 3
E6: 500 | F6: 2800 | G6: 2800 | H6: 2790 | I6: 2775 | J6: 2765 | K6: 2750 | L6: 2740 | V6: 400 | W6: 4
E7: 1000 | F7: 2800 | G7: 2800 | H7: 2775 | I7: 2765 | J7: 2750 | K7: 2725 | L7: 2690 | V7: 500 | W7: 5
E8: 1500 | F8: 2790 | G8: 2775 | H8: 2760 | I8: 2745 | J8: 2735 | K8: 2690 | L8: 2640 | V8: 600 | W8: 6
E9: 2000 | F9: 2780 | G9: 2760 | H9: 2740 | I9: 2730 | J9: 2720 | K9: 2660 | L9: 2590 | V9: 700 | W9: 7
E10: 2500 | F10: 2760 | G10: 2740 | H10: 2730 | I10: 2715 | J10: 2680 | K10: 2615 | L10: 2530 | V10: 800 | W10: 8
E11: 3000 | F11: 2740 | G11: 2725 | H11: 2710 | I11: 2675 | J11: 2640 | K11: 2560 | L11: 2485 | V11: 900 | W11: 9
E12: 3500 | F12: 2725 | G12: 2715 | H12: 2700 | I12: 2640 | J12: 2580 | K12: 2510 | L12: 2430 | V12: 1000 | W12: 10
E13: 4000 | F13: 2715 | G13: 2680 | H13: 2650 | I13: 2585 | J13: 2540 | K13: 2460 | L13: 2390 | V13: 1100 | W13: 11
V14: 1200 | W14: 12
F15: גובה נבחר | G15: =ראשי!D36 -> 2000 | J15: גובה מתחת | K15: גובה מעל | L15: ממוצע | V15: 1300 | W15: 13
F16: טמפ נבחרת | G16: =ראשי!G36 -> 20 | J16: =ROUNDDOWN(($G$15/500),0)*500 -> 2000 | K16: =ROUNDUP(($G$15/500),0)*500 -> 2000 | L16: =$G$15 -> 2000 | V16: 1400 | W16: 14
F17: מהק | G17: =$L$19+IF($G$18=TRUE,-80,0) -> 2660 | H17: טמפ מתחת | I17: =ROUNDDOWN(($G$16/5),0)*5 -> 20 | J17: =INDEX(OGEtable,MATCH(J16,$E$5:$E$13),MATCH(I17,$F$4:$L$4)) -> 2740 | K17: =INDEX(OGEtable,MATCH(K16,$E$5:$E$13),MATCH(I17,$F$4:$L$4)) -> 2740 | L17: =ROUND((K17-J17)*MOD($L$16,500)/500+J17,0) -> 2740 | V17: 1500 | W17: 15
F18: מהק 80- | G18: =maxPWRspare="מה''ק מינוס 80KG" -> TRUE | H18: טמפ מעל | I18: =ROUNDUP(($G$16/5),0)*5 -> 20 | J18: =INDEX(OGEtable,MATCH(J16,$E$5:$E$13),MATCH(I18,$F$4:$L$4)) -> 2740 | K18: =INDEX(OGEtable,MATCH(K16,$E$5:$E$13),MATCH(I18,$F$4:$L$4)) -> 2740 | L18: =ROUND((K18-J18)*MOD($L$16,500)/500+J18,0) -> 2740 | V18: 1600 | W18: 16
I19: =$G$16 -> 20 | K19: סופי | L19: =ROUND($L$17-($L$17-$L$18)*MOD($I$19,5)/5,0) -> 2740 | V19: 1700 | W19: 17
V20: 1800 | W20: 18
E21: OGE GRAPH | I21: =AND(calcMETHOD=ogeCALC,OR(userCARGOkg>0,userBAMBI="מחובר")) -> FALSE | J21: WEIGHT ON CABLE | V21: 1900 | W21: 19
F22: X | G22: Y | V22: 2000 | W22: 20
E23: FWD | F23: =($G$17-נתונים!$X$34)/נתונים!$W$34 -> 3.269 | G23: =OGE -> 2660 | V23: 2100 | W23: 21
E24: AFT | F24: =($G$17-נתונים!$X$35)/נתונים!$W$35 -> 3.4358255 | G24: =OGE -> 2660 | V24: 2200 | W24: 22
V25: 2300 | W25: 23
V26: 2400 | W26: 24
V27: 2500 | W27: 25
V28: 2600 | W28: 26
V29: 2700 | W29: 27
V30: 2800 | W30: 28
V31: 2900 | W31: 29
V32: 3000 | W32: 30
V33: 3100 | W33: 31
V34: 3200 | W34: 32
V35: 3300 | W35: 33
V36: 3400 | W36: 34
... V42: 4000 | W42: 40

Sheet גרסאות
A1: גרסה | B1: תאריך | C1: מהות העדכון | D1: ע"י
A2: 3.13 | B2: 44294 | C2: מחיקת הערה על תצורה מאושרת לתצורת FIRE עם כדור קטן בלבד | D2: בנצי
A3: 3.14 | B3: 44540 | C3: הוספת גרף ריחוף OGE בלשונית מה"ק | D3: בנצי
A4: 3.2 | B4: 44651 | C4: הרחבת תצורת CUSTOM לביצוע מתלה מטען. תיקון גרף מה"ק למרכז כובד רוחבי | D4: בנצי
A5: 3.3 | B5: 44324 | C5: עדכון נתוני שקילה ; הסרת שורת MISSION EQUIP | D5: בנצי
A6: 3.31 | B6: 44747 | C6: תיקון באג DSP בתצורת POLICE/FIRE | D6: בנצי
A7: 3.4 | B7: 44927 | C7: הוספת חישוב מתלה מטען (מלבד במבי), הגבלת 2250 פנימי | D7: בנצי
A8: 3.5 | B8: 45265 | C8: הוספת חישוב משקל פנימי 2250 ומירבי דלק בהתאם | D8: בנצי
