Workbook
Name ACT_tempK: CARGO!$K$3
Name AFTtst: נתונים!$AP$58
Name avgEQIPaftARM: נתונים!$AR$54
Name avgEQIPfwdARM: נתונים!$AR$53
Name cargoLIMITarea: CARGO100!$R$31
Name cargoLIMITarea: CARGO70!$R$31
Name cargoLIMITarea: CARGO80!$R$31
Name cargoLIMITarea: CARGO90!$R$31
Name cargoLIMITarea: CARGO!$R$31
Name cargoLMT: CARGO!$G$63
Name cargoLMTat140: CARGO!$G$65
Name cargoLMTfuel: CARGO!$AN$15:$AN$78
Name choose_pic: INDEX(תמונות!$B$2:$B$28,MATCH(תמונות!$C$2,תמונות!$A$2:$A$28,0))
Name choose_pic_main: INDEX(תמונות!$B$2:$B$28,MATCH(ראשי!$D$7,תמונות!$A$2:$A$28,0))
Name DensityAlt: CARGO!$J$6
Name externalLOADmoment: נתונים!$N$23:$N$25
Name externalLOADwt: נתונים!$L$23:$L$25
Name EXTtst: נתונים!$AP$57
Name FRconfig: FR!$D$23
Name FUEL100: נתונים!$S$91
Name FUEL70: נתונים!$S$88
Name FUEL80: נתונים!$S$89
Name FUEL90: נתונים!$S$90
Name FWDtst: נתונים!$AP$56
Name INPUT11: ראשי!$M$7
Name INPUT12: ראשי!$M$9
Name INPUT13: ראשי!$M$11
Name INPUT14: ראשי!$M$13
Name INPUT15: ראשי!$M$15
Name INPUT21: ראשי!$J$7
Name INPUT22: ראשי!$J$9
Name INPUT23: ראשי!$J$11
Name INPUT24: ראשי!$J$13
Name INPUT25: ראשי!$J$15
Name ISA_35: CARGO!$J$5
Name LAT_LOADING_TABLE: נתונים!$AP$46:$AQ$48
Name LEFTtst: נתונים!$AP$65
Name LONG_LOADING_TABLE: נתונים!$AP$38:$AR$43
Name MAX_LATdevFUEL: נתונים!$AP$69
Name MAX_LONGdevFUEL: נתונים!$AP$62
Name maxAllowedAftArm: נתונים!$AR$62
Name MAXallowedFUEL: נתונים!$T$81
Name maxAllowedFwdArm: נתונים!$AR$58
Name maxCARGO: CARGO100!$G$62
Name maxCARGO: CARGO70!$G$62
Name maxCARGO: CARGO80!$G$62
Name maxCARGO: CARGO90!$G$62
Name maxCARGO: CARGO!$G$62
Name maxGRAPH: CARGO100!$R$32
Name maxGRAPH: CARGO70!$R$32
Name maxGRAPH: CARGO80!$R$32
Name maxGRAPH: CARGO90!$R$32
Name maxGRAPH: CARGO!$R$32
Name MAXGROSS: CARGO100!$K$22
Name MAXGROSS: CARGO70!$K$22
Name MAXGROSS: CARGO80!$K$22
Name MAXGROSS: CARGO90!$K$22
Name MAXGROSS: CARGO!$K$22
Name MIN_LATdevFUEL: נתונים!$AP$68
Name MIN_LONGdevFUEL: נתונים!$AP$61

Sheet ראשי
D2: גרסה | E2: 4.1
B4: מסוק | D4: BMP
B7: תצורת כסאות | D7: 01: קבועה - 4 כסאות
B9: מערכת | D9: DSP | J9: 10
B11: XP | D11: כן
B13: כריזה | D13: כן
B15: מתלה מטען + מראות | D15: ללא מראות | F15: משקל על הוו
B17: במבי | D17: ללא | F17: =IF(AND(userCARGOwt>0,userBAMBI="מחובר"),"כשבמבי מחובר - יש לאפס משקל על הוו ",IF(AND(userBAMBI="מחובר",userCARGO="ללא"),"חיבור במבי ניתן עם מתלה מטען בלבד",""))
B19: מתקן גלישה | D19: ללא | F19: צד | H19: ימין+שמאל
B23: צוות | D23: טייס ימין | H23: טייס שמאל
D24: 80 | H24: 80
D26: 3 | F26: 2 | H26: 1 | J26: פירוט תצורה
F27: 0 | J27: =IF(sum_chairs>0,sum_chairs&" כסאות",IF(sum_palsivs>0,sum_palsivs&" פלסיב","ללא כסאות")) -> 4 כסאות
B28: תא נוסעים | D28: 6 | F28: 5 | H28: 4 | J28: ="מערכת - "&userFLIR -> מערכת - DSP
J29: ="XP - "&userXP -> XP - כן
D30: 9 | F30: 8 | H30: 7 | J30: ="מתלה מטען / מראות - "&userCARGO -> מתלה מטען / מראות - ללא מראות
J31: ="במבי - "&userBAMBI -> במבי - ללא
J32: ="מתקן גלישה - "&userFR&IF(userFR="ללא",""," / "&userFRside) -> מתקן גלישה - ללא
D33: משקל | F33: LONG | H33: LAT
B34: מטען נוסף | C34: 1)
B35: יש להזין משקל וCG | C35: 2)
C36: 3)
C37: 4) | I37: { | J37: הזנה חופשית
C38: 5)
C39: 6)
C41: גובה | D41: 2000 | F41: טמפ' | G41: 20 | J41: משקל מירבי לחישוב | L41: 3700
J43: מירבי מינוס 100kg? | L43: לא
C45: מסוק ריק | F45: =VLOOKUP($D$4,נתונים!$C$7:$D$8,2,FALSE) -> 2386.95 | J45: פריסטים לגיחה
C46: תצורה והתקנות | F46: =SUM(נתונים!$L$7:$L$19)+SUM(נתונים!$D$40:$D$51) -> 152.652 | H46: מסוק וצוות | J46: מים | L46: דלק | M46: GO/NOGO
C47: ברזל HELIONIX | F47: =SUM(F45:F46) -> 2539.602 | H47: =ROUND(SUM($F$47:$F$48),0)&" kg" -> 2700 kg | J47: 70% (476 ל') | L47: =IF(ROUND(MAXGROSS-SUM($F$47:$F$49)-0.7*680-40,0)>100,ROUND(MAXGROSS-SUM($F$47:$F$49)-0.7*680-40,0)&" kg","----") -> 484 kg | M47: =CARGO70!G65 -> GO
C48: צוות | F48: =SUM(נתונים!$D$12:$D$13) -> 160 | I48: + | J48: 80% (544 ל') | L48: =IF(ROUND(MAXGROSS-SUM($F$47:$F$49)-0.8*680-40,0)>100,ROUND(MAXGROSS-SUM($F$47:$F$49)-0.8*680-40,0)&" kg","----") -> 416 kg | M48: =CARGO80!G65 -> GO
C49: נוסעים וציוד | F49: =SUM(נתונים!$D$17:$D$35,נתונים!$L$30:$L$35) -> 0 | H49: מטען מועיל | J49: 90% (612 ל') | L49: =IF(ROUND(MAXGROSS-SUM($F$47:$F$49)-0.9*680-40,0)>100,ROUND(MAXGROSS-SUM($F$47:$F$49)-0.9*680-40,0)&" kg","----") -> 348 kg | M49: =CARGO90!G65 -> GO
C50: =IF(AND(userBAMBI="מחובר",userCARGO<>"ללא"),"במבי + מים","מטען חיצוני") -> מטען חיצוני | D50: 0 | F50: =IF(OR(userCARGO="ללא מראות",userCARGO="עם מראות"),IF(userBAMBI="מחובר",נתונים!$L$25,נתונים!$L$24),0) -> 0 | H50: =ROUND(MAXGROSS-SUM($F$47:$F$48),0)&" kg" -> 1000 kg | J50: 100% (680 ל') | L50: =IF(ROUND(MAXGROSS-SUM($F$47:$F$49)-680-40,0)>100,ROUND(MAXGROSS-SUM($F$47:$F$49)-680-40,0)&" kg","----") -> 280 kg | M50: =CARGO100!G65 -> GO
C51: דלק | D51: ="(מירבי "&IF(ROUND(MAXGROSS-SUM($F$47:$F$48)-SUM($F$49:$F$50),0)>723,723,ROUND(MAXGROSS-SUM($F$47:$F$48)-SUM($F$49:$F$50),0))&")" -> (מירבי 723) | F51: 500
C52: משקל בהמראה | E52: kg | F52: =ROUND(SUM($F$47:$F$51),0) -> 3200 | H52: =MAXGROSS&" kg" -> 3700 kg | J52: ="משקל מקסימלי אפשרי על הוו עם דלק "&userFUEL -> משקל מקסימלי אפשרי על הוו עם דלק 500 | L52: ="עד "&maxCARGO&" "&CARGO!G63 -> עד 500 (משקל)
C53: ="EXCEEDING 3700 KG IS "&IF(OR(CARGO!$M$8,CARGO!$M$9),"PROHIBITED",IF(CARGO!$M$10,"PROHIBITED FOR T/O AND LANDING","APPROVED")) -> EXCEEDING 3700 KG IS APPROVED
C55: =IF(AFTtst,"AFT CG LIMIT OUT OF RANGE",IF(FWDtst,"FWD CG LIMIT OUT OF RANGE",IF(EXTtst,"FWD CG IN EXTENDED RANGE","LONG CG LIMIT WITHIN RANGE"))) -> LONG CG LIMIT WITHIN RANGE | J55: =IF(AND(MIN(cargoLMTfuel)>0,cargoLMT="(משקל)"),"EXT CARGO WEIGHT REDUCED DUE TO CG BETWEEN "&MAX(CARGO!AN15:AN78)&" AND "&MIN(CARGO!AN15:AN78)&" KG","")
C56: =IF(MIN_LONGdevFUEL+MAX_LONGdevFUEL>0,"BETWEEN "&MAX_LONGdevFUEL&" AND "&MIN_LONGdevFUEL&" KG FUEL","")
C57: =IF(RIGHTtst,"RIGHT CG LIMIT OUT OF RANGE",IF(LEFTtst,"LEFT CG LIMIT OUT OF RANGE",""))
C58: =IF(MIN_LATdevFUEL+MAX_LATdevFUEL>0,"BETWEEN "&MIN_LATdevFUEL&" AND "&MAX_LATdevFUEL&" KG FUEL","")
...

Sheet תמונות
A1: תצורה | B1: שרטוט
A2: ='משקל מערכות'!C26 -> 01: קבועה - 4 כסאות | C2: 11: גלישה - תנינים
A3: ='משקל מערכות'!C27 -> 02: 2 כסאות / מתנא
A4: ='משקל מערכות'!C28 -> 03: בטן חלקה
A5: ='משקל מערכות'!C29 -> 04: תובלה 6 כסאות
A6: ='משקל מערכות'!C30 -> 05: תובלה - 7 כסאות
A7: ='משקל מערכות'!C31 -> 06: תובלה - 8 כסאות
A8: ='משקל מערכות'!C32 -> 07: שתפ לוחמים - ללא פלסיב
A9: ='משקל מערכות'!C33 -> 08: שתפ לוחמים - עם פלסיב
A10: ='משקל מערכות'!C34 -> 09: להבה - 4 לוחמים + ציוד + 2 כסאות
A11: ='משקל מערכות'!C35 -> 10: פינוי בהיטס
A12: ='משקל מערכות'!C36 -> 11: גלישה - תנינים
A13: ='משקל מערכות'!C37 -> 12: צניחה עם פלסיב
A14: ='משקל מערכות'!C38 -> 13: פרננדו
... A32: ='משקל מערכות'!C56 -> 0

Sheet נתונים
T2: ACTUAL FUEL TABLE | X2: LONG CG EXEED | AB2: ACTUAL FUEL TABLE2 | AI2: LONG CG EXEED2 | AW2: במבי | AX2: מערכת | AY2: זרקור | AZ2: מים (%) | BA2: משקל | BB2: דלק | BC2: משקל מירבי | BF2: FR | BG2: FR side | BH2: LongSt | BI2: LatSt | BJ2: מתלה מטען
T3: + CARGO MOST AFT CG | X3: W AFT CARGO | AB3: + CARGO MOST FWD CG | AI3: W FWD CARGO | AL3: LAT CG EXEED | AQ3: CALC CG ENV | AT3: ORIGINAL CG ENV | AW3: מחובר | AX3: ללא | AY3: לא | AZ3: 0 | BA3: 0 | BB3: 0 | BC3: 3700 | BD3: FWD1 | BE3: RIGHT | BF3: ללא | BG3: ימין+שמאל | BH3: 2000 | BI3: 1200 | BJ3: ללא
T4: MASS | U4: LONG ARM | V4: LAT ARM | X4: FWD | Y4: AFT | Z4: AFT FUEL | AB4: MASS | AC4: LONG ARM | AD4: LAT ARM | AF4: FWD FUEL | AG4: EXT FUEL | AH4: FWD | AI4: EXT | AJ4: AFT | AL4: RT | AM4: LT | AN4: LAT FUEL | AQ4: מומנט | AR4: משקל | AT4: מומנט | AU4: משקל | AW4: בבטן | AX4: SHAPO | AY4: כן | AZ4: 0.7 | BA4: 5 | BB4: 1 | BC4: 3800 | BD4: FWD2 | BE4: CENTER | BF4: מותקן | BG4: ימין | BH4: 2050 | BI4: 1150 | BJ4: ללא מראות
C5: EMPTY WEIGHT | K5: REMOVABLE EQUIPMENT | S5: משקל ללא דלק | T5: =VLOOKUP(ראשי!$D$4,נתונים!$C$56:$H$57,2,FALSE) -> 2699.602 | U5: =VLOOKUP(ראשי!$D$4,נתונים!$C$56:$H$57,3,FALSE) -> 4505.1075 | V5: =VLOOKUP(ראשי!$D$4,נתונים!$C$56:$H$57,6,FALSE) -> -5.8828587 | X5: =IF($T5<$AR$5,$U5<($T5-$AR$32)/$AQ$32,FALSE) -> FALSE | Y5: =IF($T5<$AR$5,$U5>($T5-$AR$33)/$AQ$33,FALSE) -> FALSE | Z5: =IF($Y5,0,"") | AA5: 0 | AB5: =VLOOKUP(ראשי!$D$4,נתונים!$C$61:$H$62,2,FALSE) -> 2699.602 | AC5: =VLOOKUP(ראשי!$D$4,נתונים!$C$61:$H$62,3,FALSE) -> 4505.1075 | AD5: =VLOOKUP(ראשי!$D$4,נתונים!$C$61:$H$62,6,FALSE) -> -5.8828587 | AH5: =OR($AC5<($AB5-$AR$34)/$AQ$34,$AC5<4250) -> FALSE | AI5: =IF(AB5<takeoffWT2,IF($AB5<$AR$5,$AC5<($AB5-$AR$32)/$AQ$32,FALSE),FALSE) -> FALSE | AJ5: =IF($AB5<$AR$5,$AC5>($AB5-$AR$33)/$AQ$33,FALSE) -> FALSE | AL5: =OR($AD5>$AQ$17,AND($AB5>$AR$16,$AD5>$AQ$16)) -> FALSE | AM5: =OR($AD5<$AQ$20,AND($AB5>$AR$16,$AD5<$AQ$21)) -> FALSE | AN5: =IF(OR(AL5:AM5),0,"") | AQ5: =IF(userMAXGROSS=3700,4380,4383) -> 4380 | AR5: =MAXGROSS -> 3700 | AT5: 4380 | AU5: 3700 | AW5: ללא | AX5: DSP | AZ5: 0.8 | BA5: 10 | BB5: 2 | BD5: MID1 | BE5: LEFT | BG5: שמאל | BH5: 2100 | BI5: 1100 | BJ5: עם מראות
C6: מסוק | D6: משקל | E6: LONG ARM | F6: מומנט אורכי | G6: מומנט רוחבי | H6: LAT ARM | K6: ציוד | L6: משקל | M6: LONG ARM | N6: מומנט אורכי | O6: מומנט רוחבי | P6: LAT ARM | T6: =IF($T$5+דלק!$C3>takoffweight+1,takoffweight,$T$5+דלק!$C3) -> 2709.602 | U6: =IF($T$5+דלק!$C3>takoffweight+1,INDIRECT(ADDRESS(ROW()-1,COLUMN())),($T$5*$U$5+דלק!$C3*דלק!$D3)/($T$5+דלק!$C3)) -> 4501.7782 | V6: =IF($T$5+דלק!$C3>takoffweight,INDIRECT(ADDRESS(ROW()-1,COLUMN())),($T$5*$V$5+דלק!$C3*דלק!$E3)/($T$5+דלק!$C3)) -> -5.3592288 | X6: =IF($T6<$AR$5,$U6<($T6-$AR$32)/$AQ$32,FALSE) -> FALSE | Y6: =IF($T6<$AR$5,$U6>($T6-$AR$33)/$AQ$33,FALSE) -> FALSE | Z6: =IF($Y6,דלק!$C3,"") | AA6: 10 | AB6: =IF($AB$5+דלק!$C3>takoffweight+1,takoffweight,$AB$5+דלק!$C3) -> 2709.602 | AC6: =IF($AB$5+דלק!$C3>takoffweight+1,INDIRECT(ADDRESS(ROW()-1,COLUMN())),($AB$5*$AC$5+דלק!$C3*דלק!$D3)/($AB$5+דלק!$C3)) -> 4501.7782 | AD6: =IF($AB$5+דלק!$C3>takoffweight,INDIRECT(ADDRESS(ROW()-1,COLUMN())),($AB$5*$AD$5+דלק!$C3*דלק!$E3)/($AB$5+דלק!$C3)) -> -5.3592288 | AH6: =OR($AC6<($AB6-$AR$34)/$AQ$34,$AC6<4250) -> FALSE | AI6: =IF(AB6<takeoffWT2,IF($AB6<$AR$5,$AC6<($AB6-$AR$32)/$AQ$32,FALSE),FALSE) -> FALSE | AJ6: =IF($AB6<$AR$5,$AC6>($AB6-$AR$33)/$AQ$33,FALSE) -> FALSE | AL6: =OR($AD6>$AQ$17,AND($AB6>$AR$16,$AD6>$AQ$16)) -> FALSE | AM6: =OR($AD6<$AQ$20,AND($AB6>$AR$16,$AD6<$AQ$21)) -> FALSE | AN6: =IF(OR(AL6:AM6),דלק!C3,"") | AQ6: =IF(userMAXGROSS=3700,4535,4525) -> 4535 | AR6: =AR5 -> 3700 | AT6: 4535 | AU6: =AU5 -> 3700 | AZ6: 0.9 | BA6: 15 | BB6: 3 | BD6: MID2 | BH6: 2150 | BI6: 1050
C7: BMO | D7: =ברזל!I27 -> 2390.45 | E7: =ברזל!J27 -> 4714.0336 | F7: =D7*E7 -> 11268662 | G7: =D7*H7 -> -5675.1082 | H7: =ברזל!M27 -> -2.3740753 | K7: =IF('משקל מערכות'!$B4=0,"",'משקל מערכות'!C4) | L7: =IF('משקל מערכות'!$B4=0,"",'משקל מערכות'!D4) | M7: =IF('משקל מערכות'!$B4=0,"",'משקל מערכות'!E4) | N7: =IF('משקל מערכות'!$B4=0,"",'משקל מערכות'!F4) | O7: =IF('משקל מערכות'!$B4=0,"",'משקל מערכות'!G4) | P7: =IF('משקל מערכות'!$B4=0,"",'משקל מערכות'!H4) | T7: =IF($T$5+דלק!$C4>takoffweight+1,takoffweight,$T$5+דלק!$C4) -> 2719.602 | U7: =IF($T$5+דלק!$C4>takoffweight+1,INDIRECT(ADDRESS(ROW()-1,COLUMN())),($T$5*$U$5+דלק!$C4*דלק!$D4)/($T$5+דלק!$C4)) -> 4498.4587 | V7: =IF($T$5+דלק!$C4>takoffweight,INDIRECT(ADDRESS(ROW()-1,COLUMN())),($T$5*$V$5+דלק!$C4*דלק!$E4)/($T$5+דלק!$C4)) -> -5.2733368 | X7: =IF($T7<$AR$5,$U7<($T7-$AR$32)/$AQ$32,FALSE) -> FALSE | Y7: =IF($T7<$AR$5,$U7>($T7-$AR$33)/$AQ$33,FALSE) -> FALSE | Z7: =IF($Y7,דלק!$C4,"") | AA7: 20 | AB7: =IF($AB$5+דלק!$C4>takoffweight+1,takoffweight,$AB$5+דלק!$C4) -> 2719.602 | AC7: =IF($AB$5+דלק!$C4>takoffweight+1,INDIRECT(ADDRESS(ROW()-1,COLUMN())),($AB$5*$AC$5+דלק!$C4*דלק!$D4)/($AB$5+דלק!$C4)) -> 4498.4587 | AD7: =IF($AB$5+דלק!$C4>takoffweight,INDIRECT(ADDRESS(ROW()-1,COLUMN())),($AB$5*$AD$5+דלק!$C4*דלק!$E4)/($AB$5+דלק!$C4)) -> -5.2733368 | AH7: =OR($AC7<($AB7-$AR$34)/$AQ$34,$AC7<4250) -> FALSE | AI7: =IF(AB7<takeoffWT2,IF($AB7<$AR$5,$AC7<($AB7-$AR$32)/$AQ$32,FALSE),FALSE) -> FALSE | AJ7: =IF($AB7<$AR$5,$AC7>($AB7-$AR$33)/$AQ$33,FALSE) -> FALSE | AL7: =OR($AD7>$AQ$17,AND($AB7>$AR$16,$AD7>$AQ$16)) -> FALSE | AM7: =OR($AD7<$AQ$20,AND($AB7>$AR$16,$AD7<$AQ$21)) -> FALSE | AN7: =IF(OR(AL7:AM7),דלק!C4,"") | AQ7: 4700 | AR7: 2000 | AT7: 4700 | AU7: 2000 | AZ7: 1 | BA7: 20 | BB7: 4 | BD7: AFT1 | BH7: 2200 | BI7: 1000
C8: BMP | D8: =ברזל!I28 -> 2386.95 | E8: =ברזל!J28 -> 4713.9748 | F8: =D8*E8 -> 11252022 | G8: =D8*H8 -> 2723.8228 | H8: =ברזל!M28 -> 1.1411311 | K8: =IF('משקל מערכות'!$B5=0,"",'משקל מערכות'!C5) | L8: =IF('משקל מערכות'!$B5=0,"",'משקל מערכות'!D5) | M8: =IF('משקל מערכות'!$B5=0,"",'משקל מערכות'!E5) | N8: =IF('משקל מערכות'!$B5=0,"",'משקל מערכות'!F5) | O8: =IF('משקל מערכות'!$B5=0,"",'משקל מערכות'!G5) | P8: =IF('משקל מערכות'!$B5=0,"",'משקל מערכות'!H5) | T8: =IF($T$5+דלק!$C5>takoffweight+1,takoffweight,$T$5+דלק!$C5) -> 2729.602 | U8: =IF($T$5+דלק!$C5>takoffweight+1,INDIRECT(ADDRESS(ROW()-1,COLUMN())),($T$5*$U$5+דלק!$C5*דלק!$D5)/($T$5+דלק!$C5)) -> 4495.1378 | V8: =IF($T$5+דלק!$C5>takoffweight,INDIRECT(ADDRESS(ROW()-1,COLUMN())),($T$5*$V$5+דלק!$C5*דלק!$E5)/($T$5+דלק!$C5)) -> -5.2137188 | X8: =IF($T8<$AR$5,$U8<($T8-$AR$32)/$AQ$32,FALSE) -> FALSE | Y8: =IF($T8<$AR$5,$U8>($T8-$AR$33)/$AQ$33,FALSE) -> FALSE | Z8: =IF($Y8,דלק!$C5,"") | AA8: 30 | AB8: =IF($AB$5+דלק!$C5>takoffweight+1,takoffweight,$AB$5+דלק!$C5) -> 2729.602 | AC8: =IF($AB$5+דלק!$C5>takoffweight+1,INDIRECT(ADDRESS(ROW()-1,COLUMN())),($AB$5*$AC$5+דלק!$C5*דלק!$D5)/($AB$5+דלק!$C5)) -> 4495.1378 | AD8: =IF($AB$5+דלק!$C5>takoffweight,INDIRECT(ADDRESS(ROW()-1,COLUMN())),($AB$5*$AD$5+דלק!$C5*דלק!$E5)/($AB$5+דלק!$C5)) -> -5.2137188 | AH8: =OR($AC8<($AB8-$AR$34)/$AQ$34,$AC8<4250) -> FALSE | AI8: =IF(AB8<takeoffWT2,IF($AB8<$AR$5,$AC8<($AB8-$AR$32)/$AQ$32,FALSE),FALSE) -> FALSE | AJ8: =IF($AB8<$AR$5,$AC8>($AB8-$AR$33)/$AQ$33,FALSE) -> FALSE | AL8: =OR($AD8>$AQ$17,AND($AB8>$AR$16,$AD8>$AQ$16)) -> FALSE | AM8: =OR($AD8<$AQ$20,AND($AB8>$AR$16,$AD8<$AQ$21)) -> FALSE | AN8: =IF(OR(AL8:AM8),דלק!C5,"") | AQ8: 4347 | AR8: 2400 | AT8: 4347 | AU8: 2400 | BA8: 25 | BB8: 5 | BD8: AFT2 | BH8: 2250 | BI8: 950
K9: =IF('משקל מערכות'!$B6=0,"",'משקל מערכות'!C6) -> Controp DSP-HD Camera | L9: =IF('משקל מערכות'!$B6=0,"",'משקל מערכות'!D6) -> 31.3 | M9: =IF('משקל מערכות'!$B6=0,"",'משקל מערכות'!E6) -> 2330 | N9: =IF('משקל מערכות'!$B6=0,"",'משקל מערכות'!F6) -> 72929 | O9: =IF('משקל מערכות'!$B6=0,"",'משקל מערכות'!G6) -> -31300 | P9: =IF('משקל מערכות'!$B6=0,"",'משקל מערכות'!H6) -> -1000 | T9: =IF($T$5+דלק!$C6>takoffweight+1,takoffweight,$T$5+דלק!$C6) -> 2739.602 | U9: =IF($T$5+דלק!$C6>takoffweight+1,INDIRECT(ADDRESS(ROW()-1,COLUMN())),($T$5*$U$5+דלק!$C6*דלק!$D6)/($T$5+דלק!$C6)) -> 4491.8193 | V9: =IF($T$5+דלק!$C6>takoffweight,INDIRECT(ADDRESS(ROW()-1,COLUMN())),($T$5*$V$5+דלק!$C6*דלק!$E6)/($T$5+דלק!$C6)) -> -5.1837373 | X9: =IF($T9<$AR$5,$U9<($T9-$AR$32)/$AQ$32,FALSE) -> FALSE | Y9: =IF($T9<$AR$5,$U9>($T9-$AR$33)/$AQ$33,FALSE) -> FALSE | Z9: =IF($Y9,דלק!$C6,"") | AA9: 40 | AB9: =IF($AB$5+דלק!$C6>takoffweight+1,takoffweight,$AB$5+דלק!$C6) -> 2739.602 | AC9: =IF($AB$5+דלק!$C6>takoffweight+1,INDIRECT(ADDRESS(ROW()-1,COLUMN())),($AB$5*$AC$5+דלק!$C6*דלק!$D6)/($AB$5+דלק!$C6)) -> 4491.8193 | AD9: =IF($AB$5+דלק!$C6>takoffweight,INDIRECT(ADDRESS(ROW()-1,COLUMN())),($AB$5*$AD$5+דלק!$C6*דלק!$E6)/($AB$5+דלק!$C6)) -> -5.1837373 | AH9: =OR($AC9<($AB9-$AR$34)/$AQ$34,$AC9<4250) -> FALSE | AI9: =IF(AB9<takeoffWT2,IF($AB9<$AR$5,$AC9<($AB9-$AR$32)/$AQ$32,FALSE),FALSE) -> FALSE | AJ9: =IF($AB9<$AR$5,$AC9>($AB9-$AR$33)/$AQ$33,FALSE) -> FALSE | AL9: =OR($AD9>$AQ$17,AND($AB9>$AR$16,$AD9>$AQ$16)) -> FALSE | AM9: =OR($AD9<$AQ$20,AND($AB9>$AR$16,$AD9<$AQ$21)) -> FALSE | AN9: =IF(OR(AL9:AM9),דלק!C6,"") | AQ9: =AQ5 -> 4380 | AR9: =AR5 -> 3700 | AT9: =AT5 -> 4380 | AU9: =AU5 -> 3700 | BA9: 30 | BB9: 6 | BH9: 2300 | BI9: 900
C10: CREW | K10: =IF('משקל מערכות'!$B7=0,"",'משקל מערכות'!C7) | L10: =IF('משקל מערכות'!$B7=0,"",'משקל מערכות'!D7) | M10: =IF('משקל מערכות'!$B7=0,"",'משקל מערכות'!E7) | N10: =IF('משקל מערכות'!$B7=0,"",'משקל מערכות'!F7) | O10: =IF('משקל מערכות'!$B7=0,"",'משקל מערכות'!G7) | P10: =IF('משקל מערכות'!$B7=0,"",'משקל מערכות'!H7) | T10: =IF($T$5+דלק!$C7>takoffweight+1,takoffweight,$T$5+דלק!$C7) -> 2749.602 | U10: =IF($T$5+דלק!$C7>takoffweight+1,INDIRECT(ADDRESS(ROW()-1,COLUMN())),($T$5*$U$5+דלק!$C7*דלק!$D7)/($T$5+דלק!$C7)) -> 4488.5213 | V10: =IF($T$5+דלק!$C7>takoffweight,INDIRECT(ADDRESS(ROW()-1,COLUMN())),($T$5*$V$5+דלק!$C7*דלק!$E7)/($T$5+דלק!$C7)) -> -5.1576109 | X10: =IF($T10<$AR$5,$U10<($T10-$AR$32)/$AQ$32,FALSE) -> FALSE | Y10: =IF($T10<$AR$5,$U10>($T10-$AR$33)/$AQ$33,FALSE) -> FALSE | Z10: =IF($Y10,דלק!$C7,"") | AA10: 50 | AB10: =IF($AB$5+דלק!$C7>takoffweight+1,takoffweight,$AB$5+דלק!$C7) -> 2749.602 | AC10: =IF($AB$5+דלק!$C7>takoffweight+1,INDIRECT(ADDRESS(ROW()-1,COLUMN())),($AB$5*$AC$5+דלק!$C7*דלק!$D7)/($AB$5+דלק!$C7)) -> 4488.5213 | AD10: =IF($AB$5+דלק!$C7>takoffweight,INDIRECT(ADDRESS(ROW()-1,COLUMN())),($AB$5*$AD$5+דלק!$C7*דלק!$E7)/($AB$5+דלק!$C7)) -> -5.1576109 | AH10: =OR($AC10<($AB10-$AR$34)/$AQ$34,$AC10<4250) -> FALSE | AI10: =IF(AB10<takeoffWT2,IF($AB10<$AR$5,$AC10<($AB10-$AR$32)/$AQ$32,FALSE),FALSE) -> FALSE | AJ10: =IF($AB10<$AR$5,$AC10>($AB10-$AR$33)/$AQ$33,FALSE) -> FALSE | AL10: =OR($AD10>$AQ$17,AND($AB10>$AR$16,$AD10>$AQ$16)) -> FALSE | AM10: =OR($AD10<$AQ$20,AND($AB10>$AR$16,$AD10<$AQ$21)) -> FALSE | AN10: =IF(OR(AL10:AM10),דלק!C7,"") | BA10: 35 | BB10: 7 | BH10: 2350 | BI10: 850
C11: ציוד | D11: משקל | E11: LONG ARM | F11: מומנט אורכי | G11: מומנט רוחבי | H11: LAT ARM | K11: =IF('משקל מערכות'!$B8=0,"",'משקל מערכות'!C8) -> Controp Hand Controller | L11: =IF('משקל מערכות'!$B8=0,"",'משקל מערכות'!D8) -> 0.68 | M11: =IF('משקל מערכות'!$B8=0,"",'משקל מערכות'!E8) -> 2460 | N11: =IF('משקל מערכות'!$B8=0,"",'משקל מערכות'!F8) -> 1672.8 | O11: =IF('משקל מערכות'!$B8=0,"",'משקל מערכות'!G8) -> 0 | P11: =IF('משקל מערכות'!$B8=0,"",'משקל מערכות'!H8) -> 0 | T11: =IF($T$5+דלק!$C8>takoffweight+1,takoffweight,$T$5+דלק!$C8) -> 2759.602 | U11: =IF($T$5+דלק!$C8>takoffweight+1,INDIRECT(ADDRESS(ROW()-1,COLUMN())),($T$5*$U$5+דלק!$C8*דלק!$D8)/($T$5+דלק!$C8)) -> 4485.211 | V11: =IF($T$5+דלק!$C8>takoffweight,INDIRECT(ADDRESS(ROW()-1,COLUMN())),($T$5*$V$5+דלק!$C8*דלק!$E8)/($T$5+דלק!$C8)) -> -5.1461686 | X11: =IF($T11<$AR$5,$U11<($T11-$AR$32)/$AQ$32,FALSE) -> FALSE | Y11: =IF($T11<$AR$5,$U11>($T11-$AR$33)/$AQ$33,FALSE) -> FALSE | Z11: =IF($Y11,דלק!$C8,"") | AA11: 60 | AB11: =IF($AB$5+דלק!$C8>takoffweight+1,takoffweight,$AB$5+דלק!$C8) -> 2759.602 | AC11: =IF($AB$5+דלק!$C8>takoffweight+1,INDIRECT(ADDRESS(ROW()-1,COLUMN())),($AB$5*$AC$5+דלק!$C8*דלק!$D8)/($AB$5+דלק!$C8)) -> 4485.211 | AD11: =IF($AB$5+דלק!$C8>takoffweight,INDIRECT(ADDRESS(ROW()-1,COLUMN())),($AB$5*$AD$5+דלק!$C8*דלק!$E8)/($AB$5+דלק!$C8)) -> -5.1461686 | AH11: =OR($AC11<($AB11-$AR$34)/$AQ$34,$AC11<4250) -> FALSE | AI11: =IF(AB11<takeoffWT2,IF($AB11<$AR$5,$AC11<($AB11-$AR$32)/$AQ$32,FALSE),FALSE) -> FALSE | AJ11: =IF($AB11<$AR$5,$AC11>($AB11-$AR$33)/$AQ$33,FALSE) -> FALSE | AL11: =OR($AD11>$AQ$17,AND($AB11>$AR$16,$AD11>$AQ$16)) -> FALSE | AM11: =OR($AD11<$AQ$20,AND($AB11>$AR$16,$AD11<$AQ$21)) -> FALSE | AN11: =IF(OR(AL11:AM11),דלק!C8,"") | BA11: 40 | BB11: 8 | BH11: 2400 | BI11: 800
C12: טייס ימין | D12: =ראשי!D24 -> 80 | E12: 2312 | F12: =D12*E12 -> 184960 | G12: =D12*H12 -> 31200 | H12: 390 | K12: =IF('משקל מערכות'!$B9=0,"",'משקל מערכות'!C9) -> Nightsun XP Search Light | L12: =IF('משקל מערכות'!$B9=0,"",'משקל מערכות'!D9) -> 26.31 | M12: =IF('משקל מערכות'!$B9=0,"",'משקל מערכות'!E9) -> 2630 | N12: =IF('משקל מערכות'!$B9=0,"",'משקל מערכות'!F9) -> 69195.3 | O12: =IF('משקל מערכות'!$B9=0,"",'משקל מערכות'!G9) -> 26310 | P12: =IF('משקל מערכות'!$B9=0,"",'משקל מערכות'!H9) -> 1000 | T12: =IF($T$5+דלק!$C9>takoffweight+1,takoffweight,$T$5+דלק!$C9) -> 2769.602 | U12: =IF($T$5+דלק!$C9>takoffweight+1,INDIRECT(ADDRESS(ROW()-1,COLUMN())),($T$5*$U$5+דלק!$C9*דלק!$D9)/($T$5+דלק!$C9)) -> 4481.9029 | V12: =IF($T$5+דלק!$C9>takoffweight,INDIRECT(ADDRESS(ROW()-1,COLUMN())),($T$5*$V$5+דלק!$C9*דלק!$E9)/($T$5+דלק!$C9)) -> -5.1275877 | X12: =IF($T12<$AR$5,$U12<($T12-$AR$32)/$AQ$32,FALSE) -> FALSE | Y12: =IF($T12<$AR$5,$U12>($T12-$AR$33)/$AQ$33,FALSE) -> FALSE | Z12: =IF($Y12,דלק!$C9,"") | AA12: 70 | AB12: =IF($AB$5+דלק!$C9>takoffweight+1,takoffweight,$AB$5+דלק!$C9) -> 2769.602 | AC12: =IF($AB$5+דלק!$C9>takoffweight+1,INDIRECT(ADDRESS(ROW()-1,COLUMN())),($AB$5*$AC$5+דלק!$C9*דלק!$D9)/($AB$5+דלק!$C9)) -> 4481.9029 | AD12: =IF($AB$5+דלק!$C9>takoffweight,INDIRECT(ADDRESS(ROW()-1,COLUMN())),($AB$5*$AD$5+דלק!$C9*דלק!$E9)/($AB$5+דלק!$C9)) -> -5.1275877 | AH12: =OR($AC12<($AB12-$AR$34)/$AQ$34,$AC12<4250) -> FALSE | AI12: =IF(AB12<takeoffWT2,IF($AB12<$AR$5,$AC12<($AB12-$AR$32)/$AQ$32,FALSE),FALSE) -> FALSE | AJ12: =IF($AB12<$AR$5,$AC12>($AB12-$AR$33)/$AQ$33,FALSE) -> FALSE | AL12: =OR($AD12>$AQ$17,AND($AB12>$AR$16,$AD12>$AQ$16)) -> FALSE | AM12: =OR($AD12<$AQ$20,AND($AB12>$AR$16,$AD12<$AQ$21)) -> FALSE | AN12: =IF(OR(AL12:AM12),דלק!C9,"") | AQ12: LAT CG ENV | AT12: מהק מינוס ---- | BA12: 45 | BB12: 9 | BH12: 2450 | BI12: 750
C13: טייס שמאל | D13: =ראשי!H24 -> 80 | E13: 2312 | F13: =D13*E13 -> 184960 | G13: =D13*H13 -> -31200 | H13: -390 | K13: =IF('משקל מערכות'!$B10=0,"",'משקל מערכות'!C10) -> Nightsun Hand Controller | L13: =IF('משקל מערכות'!$B10=0,"",'משקל מערכות'!D10) -> 0.68 | M13: =IF('משקל מערכות'!$B10=0,"",'משקל מערכות'!E10) -> 2790 | N13: =IF('משקל מערכות'!$B10=0,"",'משקל מערכות'!F10) -> 1897.2 | O13: =IF('משקל מערכות'!$B10=0,"",'משקל מערכות'!G10) -> -95.2 | P13: =IF('משקל מערכות'!$B10=0,"",'משקל מערכות'!H10) -> -140 | T13: =IF($T$5+דלק!$C10>takoffweight+1,takoffweight,$T$5+דלק!$C10) -> 2779.602 | U13: =IF($T$5+דלק!$C10>takoffweight+1,INDIRECT(ADDRESS(ROW()-1,COLUMN())),($T$5*$U$5+דלק!$C10*דלק!$D10)/($T$5+דלק!$C10)) -> 4478.597 | V13: =IF($T$5+דלק!$C10>takoffweight,INDIRECT(ADDRESS(ROW()-1,COLUMN())),($T$5*$V$5+דלק!$C10*דלק!$E10)/($T$5+דלק!$C10)) -> -5.1091405 | X13: =IF($T13<$AR$5,$U13<($T13-$AR$32)/$AQ$32,FALSE) -> FALSE | Y13: =IF($T13<$AR$5,$U13>($T13-$AR$33)/$AQ$33,FALSE) -> FALSE | Z13: =IF($Y13,דלק!$C10,"") | AA13: 80 | AB13: =IF($AB$5+דלק!$C10>takoffweight+1,takoffweight,$AB$5+דלק!$C10) -> 2779.602 | AC13: =IF($AB$5+דלק!$C10>takoffweight+1,INDIRECT(ADDRESS(ROW()-1,COLUMN())),($AB$5*$AC$5+דלק!$C10*דלק!$D10)/($AB$5+דלק!$C10)) -> 4478.597 | AD13: =IF($AB$5+דלק!$C10>takoffweight,INDIRECT(ADDRESS(ROW()-1,COLUMN())),($AB$5*$AD$5+דלק!$C10*דלק!$E10)/($AB$5+דלק!$C10)) -> -5.1091405 | AH13: =OR($AC13<($AB13-$AR$34)/$AQ$34,$AC13<4250) -> FALSE | AI13: =IF(AB13<takeoffWT2,IF($AB13<$AR$5,$AC13<($AB13-$AR$32)/$AQ$32,FALSE),FALSE) -> FALSE | AJ13: =IF($AB13<$AR$5,$AC13>($AB13-$AR$33)/$AQ$33,FALSE) -> FALSE | AL13: =OR($AD13>$AQ$17,AND($AB13>$AR$16,$AD13>$AQ$16)) -> FALSE | AM13: =OR($AD13<$AQ$20,AND($AB13>$AR$16,$AD13<$AQ$21)) -> FALSE | AN13: =IF(OR(AL13:AM13),דלק!C10,"") | AQ13: מומנט | AR13: משקל | AT13: =CARGO!F23 -> 4380 | AU13: =MAXGROSS -> 3700 | AW13: =IF(MAXGROSS=3600,CARGO!G23,AR5) -> 3700 | BA13: 50 | BB13: 10 | BH13: 2500 | BI13: 700
K14: =IF('משקל מערכות'!$B11=0,"",'משקל מערכות'!C11) -> PA Speakers | L14: =IF('משקל מערכות'!$B11=0,"",'משקל מערכות'!D11) -> 13.52 | M14: =IF('משקל מערכות'!$B11=0,"",'משקל מערכות'!E11) -> 5810 | N14: =IF('משקל מערכות'!$B11=0,"",'משקל מערכות'!F11) -> 78551.2 | O14: =IF('משקל מערכות'!$B11=0,"",'משקל מערכות'!G11) -> -13520 | P14: =IF('משקל מערכות'!$B11=0,"",'משקל מערכות'!H11) -> -1000 | T14: =IF($T$5+דלק!$C11>takoffweight+1,takoffweight,$T$5+דלק!$C11) -> 2789.602 | U14: =IF($T$5+דלק!$C11>takoffweight+1,INDIRECT(ADDRESS(ROW()-1,COLUMN())),($T$5*$U$5+דלק!$C11*דלק!$D11)/($T$5+דלק!$C11)) -> 4475.3256 | V14: =IF($T$5+דלק!$C11>takoffweight,INDIRECT(ADDRESS(ROW()-1,COLUMN())),($T$5*$V$5+דלק!$C11*דלק!$E11)/($T$5+דלק!$C11)) -> -5.0800714 | X14: =IF($T14<$AR$5,$U14<($T14-$AR$32)/$AQ$32,FALSE) -> FALSE | Y14: =IF($T14<$AR$5,$U14>($T14-$AR$33)/$AQ$33,FALSE) -> FALSE | Z14: =IF($Y14,דלק!$C11,"") | AA14: 90 | AB14: =IF($AB$5+דלק!$C11>takoffweight+1,takoffweight,$AB$5+דלק!$C11) -> 2789.602 | AC14: =IF($AB$5+דלק!$C11>takoffweight+1,INDIRECT(ADDRESS(ROW()-1,COLUMN())),($AB$5*$AC$5+דלק!$C11*דלק!$D11)/($AB$5+דלק!$C11)) -> 4475.3256 | AD14: =IF($AB$5+דלק!$C11>takoffweight,INDIRECT(ADDRESS(ROW()-1,COLUMN())),($AB$5*$AD$5+דלק!$C11*דלק!$E11)/($AB$5+דלק!$C11)) -> -5.0800714 | AH14: =OR($AC14<($AB14-$AR$34)/$AQ$34,$AC14<4250) -> FALSE | AI14: =IF(AB14<takeoffWT2,IF($AB14<$AR$5,$AC14<($AB14-$AR$32)/$AQ$32,FALSE),FALSE) -> FALSE | AJ14: =IF($AB14<$AR$5,$AC14>($AB14-$AR$33)/$AQ$33,FALSE) -> FALSE | AL14: =OR($AD14>$AQ$17,AND($AB14>$AR$16,$AD14>$AQ$16)) -> FALSE | AM14: =OR($AD14<$AQ$20,AND($AB14>$AR$16,$AD14<$AQ$21)) -> FALSE | AN14: =IF(OR(AL14:AM14),דלק!C11,"") | AQ14: -80 | AR14: =MAXGROSS -> 3700 | AT14: =CARGO!F24 -> 4535 | AU14: =MAXGROSS -> 3700 | BA14: 55 | BB14: 11 | BH14: 2550 | BI14: 650
C15: PASSENGER AND CARGO WEIGHT | K15: =IF('משקל מערכות'!$B12=0,"",'משקל מערכות'!C12) | L15: =IF('משקל מערכות'!$B12=0,"",'משקל מערכות'!D12) | M15: =IF('משקל מערכות'!$B12=0,"",'משקל מערכות'!E12) | N15: =IF('משקל מערכות'!$B12=0,"",'משקל מערכות'!F12) | O15: =IF('משקל מערכות'!$B12=0,"",'משקל מערכות'!G12) | P15: =IF('משקל מערכות'!$B12=0,"",'משקל מערכות'!H12) | T15: =IF($T$5+דלק!$C12>takoffweight+1,takoffweight,$T$5+דלק!$C12) -> 2799.602 | U15: =IF($T$5+דלק!$C12>takoffweight+1,INDIRECT(ADDRESS(ROW()-1,COLUMN())),($T$5*$U$5+דלק!$C12*דלק!$D12)/($T$5+דלק!$C12)) -> 4472.0633 | V15: =IF($T$5+דלק!$C12>takoffweight,INDIRECT(ADDRESS(ROW()-1,COLUMN())),($T$5*$V$5+דלק!$C12*דלק!$E12)/($T$5+דלק!$C12)) -> -5.0654976 | X15: =IF($T15<$AR$5,$U15<($T15-$AR$32)/$AQ$32,FALSE) -> FALSE | Y15: =IF($T15<$AR$5,$U15>($T15-$AR$33)/$AQ$33,FALSE) -> FALSE | Z15: =IF($Y15,דלק!$C12,"") | AA15: 100 | AB15: =IF($AB$5+דלק!$C12>takoffweight+1,takoffweight,$AB$5+דלק!$C12) -> 2799.602 | AC15: =IF($AB$5+דלק!$C12>takoffweight+1,INDIRECT(ADDRESS(ROW()-1,COLUMN())),($AB$5*$AC$5+דלק!$C12*דלק!$D12)/($AB$5+דלק!$C12)) -> 4472.0633 | AD15: =IF($AB$5+דלק!$C12>takoffweight,INDIRECT(ADDRESS(ROW()-1,COLUMN())),($AB$5*$AD$5+דלק!$C12*דלק!$E12)/($AB$5+דלק!$C12)) -> -5.0654976 | AF15: =IF($AH15,דלק!$C12,"") | AG15: =IF($AI15,דלק!$C12,"") | AH15: =OR($AC15<($AB15-$AR$34)/$AQ$34,$AC15<4250) -> FALSE | AI15: =IF(AB15<takeoffWT2,IF($AB15<$AR$5,$AC15<($AB15-$AR$32)/$AQ$32,FALSE),FALSE) -> FALSE | AJ15: =IF($AB15<$AR$5,$AC15>($AB15-$AR$33)/$AQ$33,FALSE) -> FALSE | AL15: =OR($AD15>$AQ$17,AND($AB15>$AR$16,$AD15>$AQ$16)) -> FALSE | AM15: =OR($AD15<$AQ$20,AND($AB15>$AR$16,$AD15<$AQ$21)) -> FALSE | AN15: =IF(OR(AL15:AM15),דלק!C12,"") | AQ15: 80 | AR15: =MAXGROSS -> 3700 | BA15: 60 | BB15: 12 | BH15: 2600 | BI15: 600
C16: כסא | D16: משקל | E16: LONG ARM | F16: מומנט אורכי | G16: מומנט רוחבי | H16: LAT ARM | I16: קוד תצורה | K16: =IF('משקל מערכות'!$B13=0,"",'משקל מערכות'!C13) | L16: =IF('משקל מערכות'!$B13=0,"",'משקל מערכות'!D13) | M16: =IF('משקל מערכות'!$B13=0,"",'משקל מערכות'!E13) | N16: =IF('משקל מערכות'!$B13=0,"",'משקל מערכות'!F13) | O16: =IF('משקל מערכות'!$B13=0,"",'משקל מערכות'!G13) | P16: =IF('משקל מערכות'!$B13=0,"",'משקל מערכות'!H13) | T16: =IF($T$5+דלק!$C13>takoffweight+1,takoffweight,$T$5+דלק!$C13) -> 2809.602 | U16: =IF($T$5+דלק!$C13>takoffweight+1,INDIRECT(ADDRESS(ROW()-1,COLUMN())),($T$5*$U$5+דלק!$C13*דלק!$D13)/($T$5+דלק!$C13)) -> 4468.8491 | V16: =IF($T$5+דלק!$C13>takoffweight,INDIRECT(ADDRESS(ROW()-1,COLUMN())),($T$5*$V$5+דלק!$C13*דלק!$E13)/($T$5+דלק!$C13)) -> -5.0652645 | X16: =IF($T16<$AR$5,$U16<($T16-$AR$32)/$AQ$32,FALSE) -> FALSE | Y16: =IF($T16<$AR$5,$U16>($T16-$AR$33)/$AQ$33,FALSE) -> FALSE | Z16: =IF($Y16,דלק!$C13,"") | AA16: 110 | AB16: =IF($AB$5+דלק!$C13>takoffweight+1,takoffweight,$AB$5+דלק!$C13) -> 2809.602 | AC16: =IF($AB$5+דלק!$C13>takoffweight+1,INDIRECT(ADDRESS(ROW()-1,COLUMN())),($AB$5*$AC$5+דלק!$C13*דלק!$D13)/($AB$5+דלק!$C13)) -> 4468.8491 | AD16: =IF($AB$5+דלק!$C13>takoffweight,INDIRECT(ADDRESS(ROW()-1,COLUMN())),($AB$5*$AD$5+דלק!$C13*דלק!$E13)/($AB$5+דלק!$C13)) -> -5.0652645 | AF16: =IF($AH16,דלק!$C13,"") | AG16: =IF($AI16,דלק!$C13,"") | AH16: =OR($AC16<($AB16-$AR$34)/$AQ$34,$AC16<4250) -> FALSE | AI16: =IF(AB16<takeoffWT2,IF($AB16<$AR$5,$AC16<($AB16-$AR$32)/$AQ$32,FALSE),FALSE) -> FALSE | AJ16: =IF($AB16<$AR$5,$AC16>($AB16-$AR$33)/$AQ$33,FALSE) -> FALSE | AL16: =OR($AD16>$AQ$17,AND($AB16>$AR$16,$AD16>$AQ$16)) -> FALSE | AM16: =OR($AD16<$AQ$20,AND($AB16>$AR$16,$AD16<$AQ$21)) -> FALSE | AN16: =IF(OR(AL16:AM16),דלק!C13,"") | AQ16: 80 | AR16: 3000 | AT16: EXTENDED ENV | BA16: 65 | BB16: 13 | BH16: 2650 | BI16: 550
C17: 1 | D17: =IF(E17="","",ראשי!H27) -> 0 | E17: =IFERROR(INDEX($E$40:$H$51,MATCH($C17,$I$40:$I$51,0),1),"") -> 3265 | F17: =IF(E17<>"",D17*E17,"") -> 0 | G17: =IF(E17<>"",D17*H17,"") -> 0 | H17: =IFERROR(INDEX($E$40:$H$51,MATCH($C17,$I$40:$I$51,0),4),"") -> -550 | K17: =IF('משקל מערכות'!$B14=0,"",'משקל מערכות'!C14) -> CARGO HOOK DOUBLE DET PROVISIONS | L17: =IF('משקל מערכות'!$B14=0,"",'משקל מערכות'!D14) -> 29.77 | M17: =IF('משקל מערכות'!$B14=0,"",'משקל מערכות'!E14) -> 4121 | N17: =IF('משקל מערכות'!$B14=0,"",'משקל מערכות'!F14) -> 122682.17 | O17: =IF('משקל מערכות'!$B14=0,"",'משקל מערכות'!G14) -> 0 | P17: =IF('משקל מערכות'!$B14=0,"",'משקל מערכות'!H14) -> 0 | T17: =IF($T$5+דלק!$C14>takoffweight+1,takoffweight,$T$5+דלק!$C14) -> 2819.602 | U17: =IF($T$5+דלק!$C14>takoffweight+1,INDIRECT(ADDRESS(ROW()-1,COLUMN())),($T$5*$U$5+דלק!$C14*דלק!$D14)/($T$5+דלק!$C14)) -> 4465.608 | V17: =IF($T$5+דלק!$C14>takoffweight,INDIRECT(ADDRESS(ROW()-1,COLUMN())),($T$5*$V$5+דלק!$C14*דלק!$E14)/($T$5+דלק!$C14)) -> -5.0366602 | X17: =IF($T17<$AR$5,$U17<($T17-$AR$32)/$AQ$32,FALSE) -> FALSE | Y17: =IF($T17<$AR$5,$U17>($T17-$AR$33)/$AQ$33,FALSE) -> FALSE | Z17: =IF($Y17,דלק!$C14,"") | AA17: 120 | AB17: =IF($AB$5+דלק!$C14>takoffweight+1,takoffweight,$AB$5+דלק!$C14) -> 2819.602 | AC17: =IF($AB$5+דלק!$C14>takoffweight+1,INDIRECT(ADDRESS(ROW()-1,COLUMN())),($AB$5*$AC$5+דלק!$C14*דלק!$D14)/($AB$5+דלק!$C14)) -> 4465.608 | AD17: =IF($AB$5+דלק!$C14>takoffweight,INDIRECT(ADDRESS(ROW()-1,COLUMN())),($AB$5*$AD$5+דלק!$C14*דלק!$E14)/($AB$5+דלק!$C14)) -> -5.0366602 | AF17: =IF($AH17,דלק!$C14,"") | AG17: =IF($AI17,דלק!$C14,"") | AH17: =OR($AC17<($AB17-$AR$34)/$AQ$34,$AC17<4250) -> FALSE | AI17: =IF(AB17<takeoffWT2,IF($AB17<$AR$5,$AC17<($AB17-$AR$32)/$AQ$32,FALSE),FALSE) -> FALSE | AJ17: =IF($AB17<$AR$5,$AC17>($AB17-$AR$33)/$AQ$33,FALSE) -> FALSE | AL17: =OR($AD17>$AQ$17,AND($AB17>$AR$16,$AD17>$AQ$16)) -> FALSE | AM17: =OR($AD17<$AQ$20,AND($AB17>$AR$16,$AD17<$AQ$21)) -> FALSE | AN17: =IF(OR(AL17:AM17),דלק!C14,"") | AQ17: 100 | AR17: 3000 | AT17: מומנט | AU17: משקל | BA17: 70 | BB17: 14 | BH17: 2700 | BI17: 500
C18: 2 | D18: =IF(E18="","",ראשי!F27) | E18: =IFERROR(INDEX($E$40:$H$51,MATCH($C18,$I$40:$I$51,0),1),"") | F18: =IF(E18<>"",D18*E18,"") | G18: =IF(E18<>"",D18*H18,"") | H18: =IFERROR(INDEX($E$40:$H$51,MATCH($C18,$I$40:$I$51,0),4),"") | K18: =IF('משקל מערכות'!$B15=0,"",'משקל מערכות'!C15) | L18: =IF('משקל מערכות'!$B15=0,"",'משקל מערכות'!D15) | M18: =IF('משקל מערכות'!$B15=0,"",'משקל מערכות'!E15) | N18: =IF('משקל מערכות'!$B15=0,"",'משקל מערכות'!F15) | O18: =IF('משקל מערכות'!$B15=0,"",'משקל מערכות'!G15) | P18: =IF('משקל מערכות'!$B15=0,"",'משקל מערכות'!H15) | T18: =IF($T$5+דלק!$C15>takoffweight+1,takoffweight,$T$5+דלק!$C15) -> 2829.602 | U18: =IF($T$5+דלק!$C15>takoffweight+1,INDIRECT(ADDRESS(ROW()-1,COLUMN())),($T$5*$U$5+דלק!$C15*דלק!$D15)/($T$5+דלק!$C15)) -> 4462.4217 | V18: =IF($T$5+דלק!$C15>takoffweight,INDIRECT(ADDRESS(ROW()-1,COLUMN())),($T$5*$V$5+דלק!$C15*דלק!$E15)/($T$5+דלק!$C15)) -> -5.0153263 | X18: =IF($T18<$AR$5,$U18<($T18-$AR$32)/$AQ$32,FALSE) -> FALSE | Y18: =IF($T18<$AR$5,$U18>($T18-$AR$33)/$AQ$33,FALSE) -> FALSE | Z18: =IF($Y18,דלק!$C15,"") | AA18: 130 | AB18: =IF($AB$5+דלק!$C15>takoffweight+1,takoffweight,$AB$5+דלק!$C15) -> 2829.602 | AC18: =IF($AB$5+דלק!$C15>takoffweight+1,INDIRECT(ADDRESS(ROW()-1,COLUMN())),($AB$5*$AC$5+דלק!$C15*דלק!$D15)/($AB$5+דלק!$C15)) -> 4462.4217 | AD18: =IF($AB$5+דלק!$C15>takoffweight,INDIRECT(ADDRESS(ROW()-1,COLUMN())),($AB$5*$AD$5+דלק!$C15*דלק!$E15)/($AB$5+דלק!$C15)) -> -5.0153263 | AF18: =IF($AH18,דלק!$C15,"") | AG18: =IF($AI18,דלק!$C15,"") | AH18: =OR($AC18<($AB18-$AR$34)/$AQ$34,$AC18<4250) -> FALSE | AI18: =IF(AB18<takeoffWT2,IF($AB18<$AR$5,$AC18<($AB18-$AR$32)/$AQ$32,FALSE),FALSE) -> FALSE | AJ18: =IF($AB18<$AR$5,$AC18>($AB18-$AR$33)/$AQ$33,FALSE) -> FALSE | AL18: =OR($AD18>$AQ$17,AND($AB18>$AR$16,$AD18>$AQ$16)) -> FALSE | AM18: =OR($AD18<$AQ$20,AND($AB18>$AR$16,$AD18<$AQ$21)) -> FALSE | AN18: =IF(OR(AL18:AM18),דלק!C15,"") | AQ18: 100 | AR18: 2000 | AT18: 4250 | AU18: 3000 | BA18: 75 | BB18: 15 | BH18: 2750 | BI18: 450
C19: 3 | D19: =IF(E19="","",ראשי!D27) -> 0 | E19: =IFERROR(INDEX($E$40:$H$51,MATCH($C19,$I$40:$I$51,0),1),"") -> 3265 | F19: =IF(E19<>"",D19*E19,"") -> 0 | G19: =IF(E19<>"",D19*H19,"") -> 0 | H19: =IFERROR(INDEX($E$40:$H$51,MATCH($C19,$I$40:$I$51,0),4),"") -> 550 | K19: =IF('משקל מערכות'!$B16=0,"",'משקל מערכות'!C16) | L19: =IF('משקל מערכות'!$B16=0,"",'משקל מערכות'!D16) | M19: =IF('משקל מערכות'!$B16=0,"",'משקל מערכות'!E16) | N19: =IF('משקל מערכות'!$B16=0,"",'משקל מערכות'!F16) | O19: =IF('משקל מערכות'!$B16=0,"",'משקל מערכות'!G16) | P19: =IF('משקל מערכות'!$B16=0,"",'משקל מערכות'!H16) | T19: =IF($T$5+דלק!$C16>takoffweight+1,takoffweight,$T$5+דלק!$C16) -> 2839.602 | U19: =IF($T$5+דלק!$C16>takoffweight+1,INDIRECT(ADDRESS(ROW()-1,COLUMN())),($T$5*$U$5+דלק!$C16*דלק!$D16)/($T$5+דלק!$C16)) -> 4461.7652 | V19: =IF($T$5+דלק!$C16>takoffweight,INDIRECT(ADDRESS(ROW()-1,COLUMN())),($T$5*$V$5+דלק!$C16*דלק!$E16)/($T$5+דלק!$C16)) -> -5.0011858 | X19: =IF($T19<$AR$5,$U19<($T19-$AR$32)/$AQ$32,FALSE) -> FALSE | Y19: =IF($T19<$AR$5,$U19>($T19-$AR$33)/$AQ$33,FALSE) -> FALSE | Z19: =IF($Y19,דלק!$C16,"") | AA19: 140 | AB19: =IF($AB$5+דלק!$C16>takoffweight+1,takoffweight,$AB$5+דלק!$C16) -> 2839.602 | AC19: =IF($AB$5+דלק!$C16>takoffweight+1,INDIRECT(ADDRESS(ROW()-1,COLUMN())),($AB$5*$AC$5+דלק!$C16*דלק!$D16)/($AB$5+דלק!$C16)) -> 4461.7652 | AD19: =IF($AB$5+דלק!$C16>takoffweight,INDIRECT(ADDRESS(ROW()-1,COLUMN())),($AB$5*$AD$5+דלק!$C16*דלק!$E16)/($AB$5+דלק!$C16)) -> -5.0011858 | AF19: =IF($AH19,דלק!$C16,"") | AG19: =IF($AI19,דלק!$C16,"") | AH19: =OR($AC19<($AB19-$AR$34)/$AQ$34,$AC19<4250) -> FALSE | AI19: =IF(AB19<takeoffWT2,IF($AB19<$AR$5,$AC19<($AB19-$AR$32)/$AQ$32,FALSE),FALSE) -> FALSE | AJ19: =IF($AB19<$AR$5,$AC19>($AB19-$AR$33)/$AQ$33,FALSE) -> FALSE | AL19: =OR($AD19>$AQ$17,AND($AB19>$AR$16,$AD19>$AQ$16)) -> FALSE | AM19: =OR($AD19<$AQ$20,AND($AB19>$AR$16,$AD19<$AQ$21)) -> FALSE | AN19: =IF(OR(AL19:AM19),דלק!C16,"") | AQ19: -100 | AR19: 2000 | AT19: 4250 | AU19: 3700 | BA19: 80 | BB19: 16 | BH19: 2800 | BI19: 400
C20: 4 | D20: =IF(E20="","",ראשי!H29) -> 0 | E20: =IFERROR(INDEX($E$40:$H$51,MATCH($C20,$I$40:$I$51,0),1),"") -> 4400 | F20: =IF(E20<>"",D20*E20,"") -> 0 | G20: =IF(E20<>"",D20*H20,"") -> 0 | H20: =IFERROR(INDEX($E$40:$H$51,MATCH($C20,$I$40:$I$51,0),4),"") -> -369 | T20: =IF($T$5+דלק!$C17>takoffweight+1,takoffweight,$T$5+דלק!$C17) -> 2849.602 | U20: =IF($T$5+דלק!$C17>takoffweight+1,INDIRECT(ADDRESS(ROW()-1,COLUMN())),($T$5*$U$5+דלק!$C17*דלק!$D17)/($T$5+דלק!$C17)) -> 4461.8327 | V20: =IF($T$5+דלק!$C17>takoffweight,INDIRECT(ADDRESS(ROW()-1,COLUMN())),($T$5*$V$5+דלק!$C17*דלק!$E17)/($T$5+דלק!$C17)) -> -4.9941631 | X20: =IF($T20<$AR$5,$U20<($T20-$AR$32)/$AQ$32,FALSE) -> FALSE | Y20: =IF($T20<$AR$5,$U20>($T20-$AR$33)/$AQ$33,FALSE) -> FALSE | Z20: =IF($Y20,דלק!$C17,"") | AA20: 150 | AB20: =IF($AB$5+דלק!$C17>takoffweight+1,takoffweight,$AB$5+דלק!$C17) -> 2849.602 | AC20: =IF($AB$5+דלק!$C17>takoffweight+1,INDIRECT(ADDRESS(ROW()-1,COLUMN())),($AB$5*$AC$5+דלק!$C17*דלק!$D17)/($AB$5+דלק!$C17)) -> 4461.8327 | AD20: =IF($AB$5+דלק!$C17>takoffweight,INDIRECT(ADDRESS(ROW()-1,COLUMN())),($AB$5*$AD$5+דלק!$C17*דלק!$E17)/($AB$5+דלק!$C17)) -> -4.9941631 | AF20: =IF($AH20,דלק!$C17,"") | AG20: =IF($AI20,דלק!$C17,"") | AH20: =OR($AC20<($AB20-$AR$34)/$AQ$34,$AC20<4250) -> FALSE | AI20: =IF(AB20<takeoffWT2,IF($AB20<$AR$5,$AC20<($AB20-$AR$32)/$AQ$32,FALSE),FALSE) -> FALSE | AJ20: =IF($AB20<$AR$5,$AC20>($AB20-$AR$33)/$AQ$33,FALSE) -> FALSE | AL20: =OR($AD20>$AQ$17,AND($AB20>$AR$16,$AD20>$AQ$16)) -> FALSE | AM20: =OR($AD20<$AQ$20,AND($AB20>$AR$16,$AD20<$AQ$21)) -> FALSE | AN20: =IF(OR(AL20:AM20),דלק!C17,"") | AQ20: -100 | AR20: 3000 | AT20: 4380 | AU20: 3700 | BA20: 85 | BB20: 17 | BH20: 2850 | BI20: 350
C21: 5 | D21: =IF(E21="","",ראשי!F29) | E21: =IFERROR(INDEX($E$40:$H$51,MATCH($C21,$I$40:$I$51,0),1),"") | F21: =IF(E21<>"",D21*E21,"") | G21: =IF(E21<>"",D21*H21,"") | H21: =IFERROR(INDEX($E$40:$H$51,MATCH($C21,$I$40:$I$51,0),4),"") | K21: EXTERNAL LOAD | T21: =IF($T$5+דלק!$C18>takoffweight+1,takoffweight,$T$5+דלק!$C18) -> 2859.602 | U21: =IF($T$5+דלק!$C18>takoffweight+1,INDIRECT(ADDRESS(ROW()-1,COLUMN())),($T$5*$U$5+דלק!$C18*דלק!$D18)/($T$5+דלק!$C18)) -> 4461.9626 | V21: =IF($T$5+דלק!$C18>takoffweight,INDIRECT(ADDRESS(ROW()-1,COLUMN())),($T$5*$V$5+דלק!$C18*דלק!$E18)/($T$5+דלק!$C18)) -> -4.9382317 | X21: =IF($T21<$AR$5,$U21<($T21-$AR$32)/$AQ$32,FALSE) -> FALSE | Y21: =IF($T21<$AR$5,$U21>($T21-$AR$33)/$AQ$33,FALSE) -> FALSE | Z21: =IF($Y21,דלק!$C18,"") | AA21: 160 | AB21: =IF($AB$5+דלק!$C18>takoffweight+1,takoffweight,$AB$5+דלק!$C18) -> 2859.602 | AC21: =IF($AB$5+דלק!$C18>takoffweight+1,INDIRECT(ADDRESS(ROW()-1,COLUMN())),($AB$5*$AC$5+דלק!$C18*דלק!$D18)/($AB$5+דלק!$C18)) -> 4461.9626 | AD21: =IF($AB$5+דלק!$C18>takoffweight,INDIRECT(ADDRESS(ROW()-1,COLUMN())),($AB$5*$AD$5+דלק!$C18*דלק!$E18)/($AB$5+דלק!$C18)) -> -4.9382317 | AF21: =IF($AH21,דלק!$C18,"") | AG21: =IF($AI21,דלק!$C18,"") | AH21: =OR($AC21<($AB21-$AR$34)/$AQ$34,$AC21<4250) -> FALSE | AI21: =IF(AB21<takeoffWT2,IF($AB21<$AR$5,$AC21<($AB21-$AR$32)/$AQ$32,FALSE),FALSE) -> FALSE | AJ21: =IF($AB21<$AR$5,$AC21>($AB21-$AR$33)/$AQ$33,FALSE) -> FALSE | AL21: =OR($AD21>$AQ$17,AND($AB21>$AR$16,$AD21>$AQ$16)) -> FALSE | AM21: =OR($AD21<$AQ$20,AND($AB21>$AR$16,$AD21<$AQ$21)) -> FALSE | AN21: =IF(OR(AL21:AM21),דלק!C18,"") | AQ21: -80 | AR21: 3000 | AT21: 4347 | AU21: 2400 | BA21: 90 | BB21: 18 | BH21: 2900 | BI21: 300
C22: 6 | D22: =IF(E22="","",ראשי!D29) -> 0 | E22: =IFERROR(INDEX($E$40:$H$51,MATCH($C22,$I$40:$I$51,0),1),"") -> 4400 | F22: =IF(E22<>"",D22*E22,"") -> 0 | G22: =IF(E22<>"",D22*H22,"") -> 0 | H22: =IFERROR(INDEX($E$40:$H$51,MATCH($C22,$I$40:$I$51,0),4),"") -> 369 | K22: ציוד | L22: משקל | M22: LONG ARM | N22: מומנט אורכי | O22: מומנט רוחבי | P22: LAT ARM | T22: =IF($T$5+דלק!$C19>takoffweight+1,takoffweight,$T$5+דלק!$C19) -> 2869.602 | U22: =IF($T$5+דלק!$C19>takoffweight+1,INDIRECT(ADDRESS(ROW()-1,COLUMN())),($T$5*$U$5+דלק!$C19*דלק!$D19)/($T$5+דלק!$C19)) -> 4462.0325 | V22: =IF($T$5+דלק!$C19>takoffweight,INDIRECT(ADDRESS(ROW()-1,COLUMN())),($T$5*$V$5+דלק!$C19*דלק!$E19)/($T$5+דלק!$C19)) -> -4.9419317 | X22: =IF($T22<$AR$5,$U22<($T22-$AR$32)/$AQ$32,FALSE) -> FALSE | Y22: =IF($T22<$AR$5,$U22>($T22-$AR$33)/$AQ$33,FALSE) -> FALSE | Z22: =IF($Y22,דלק!$C19,"") | AA22: 170 | AB22: =IF($AB$5+דלק!$C19>takoffweight+1,takoffweight,$AB$5+דלק!$C19) -> 2869.602 | AC22: =IF($AB$5+דלק!$C19>takoffweight+1,INDIRECT(ADDRESS(ROW()-1,COLUMN())),($AB$5*$AC$5+דלק!$C19*דלק!$D19)/($AB$5+דלק!$C19)) -> 4462.0325 | AD22: =IF($AB$5+דלק!$C19>takoffweight,INDIRECT(ADDRESS(ROW()-1,COLUMN())),($AB$5*$AD$5+דלק!$C19*דלק!$E19)/($AB$5+דלק!$C19)) -> -4.9419317 | AF22: =IF($AH22,דלק!$C19,"") | AG22: =IF($AI22,דלק!$C19,"") | AH22: =OR($AC22<($AB22-$AR$34)/$AQ$34,$AC22<4250) -> FALSE | AI22: =IF(AB22<takeoffWT2,IF($AB22<$AR$5,$AC22<($AB22-$AR$32)/$AQ$32,FALSE),FALSE) -> FALSE | AJ22: =IF($AB22<$AR$5,$AC22>($AB22-$AR$33)/$AQ$33,FALSE) -> FALSE | AL22: =OR($AD22>$AQ$17,AND($AB22>$AR$16,$AD22>$AQ$16)) -> FALSE | AM22: =OR($AD22<$AQ$20,AND($AB22>$AR$16,$AD22<$AQ$21)) -> FALSE | AN22: =IF(OR(AL22:AM22),דלק!C19,"") | AQ22: -80 | AR22: =MAXGROSS -> 3700 | AT22: 4250 | AU22: 3000 | BA22: 95 | BB22: 19 | BH22: 2950 | BI22: 250
C23: 7 | D23: =IF(E23="","",ראשי!H31) | E23: =IFERROR(INDEX($E$40:$H$51,MATCH($C23,$I$40:$I$51,0),1),"") | F23: =IF(E23<>"",D23*E23,"") | G23: =IF(E23<>"",D23*H23,"") | H23: =IFERROR(INDEX($E$40:$H$51,MATCH($C23,$I$40:$I$51,0),4),"") | K23: =IF('משקל מערכות'!$B17=0,"",'משקל מערכות'!C17) | L23: =IF('משקל מערכות'!$B17=0,"",'משקל מערכות'!D17) | M23: =IF('משקל מערכות'!$B17=0,"",'משקל מערכות'!E17) | N23: =IF('משקל מערכות'!$B17=0,"",'משקל מערכות'!F17) | O23: =IF('משקל מערכות'!$B17=0,"",'משקל מערכות'!G17) | P23: =IF('משקל מערכות'!$B17=0,"",'משקל מערכות'!H17) | T23: =IF($T$5+דלק!$C20>takoffweight+1,takoffweight,$T$5+דלק!$C20) -> 2879.602 | U23: =IF($T$5+דלק!$C20>takoffweight+1,INDIRECT(ADDRESS(ROW()-1,COLUMN())),($T$5*$U$5+דלק!$C20*דלק!$D20)/($T$5+דלק!$C20)) -> 4462.1574 | V23: =IF($T$5+דלק!$C20>takoffweight,INDIRECT(ADDRESS(ROW()-1,COLUMN())),($T$5*$V$5+דלק!$C20*דלק!$E20)/($T$5+דלק!$C20)) -> -4.9525515 | X23: =IF($T23<$AR$5,$U23<($T23-$AR$32)/$AQ$32,FALSE) -> FALSE | Y23: =IF($T23<$AR$5,$U23>($T23-$AR$33)/$AQ$33,FALSE) -> FALSE | Z23: =IF($Y23,דלק!$C20,"") | AA23: 180 | AB23: =IF($AB$5+דלק!$C20>takoffweight+1,takoffweight,$AB$5+דלק!$C20) -> 2879.602 | AC23: =IF($AB$5+דלק!$C20>takoffweight+1,INDIRECT(ADDRESS(ROW()-1,COLUMN())),($AB$5*$AC$5+דלק!$C20*דלק!$D20)/($AB$5+דלק!$C20)) -> 4462.1574 | AD23: =IF($AB$5+דלק!$C20>takoffweight,INDIRECT(ADDRESS(ROW()-1,COLUMN())),($AB$5*$AD$5+דלק!$C20*דלק!$E20)/($AB$5+דלק!$C20)) -> -4.9525515 | AF23: =IF($AH23,דלק!$C20,"") | AG23: =IF($AI23,דלק!$C20,"") | AH23: =OR($AC23<($AB23-$AR$34)/$AQ$34,$AC23<4250) -> FALSE | AI23: =IF(AB23<takeoffWT2,IF($AB23<$AR$5,$AC23<($AB23-$AR$32)/$AQ$32,FALSE),FALSE) -> FALSE | AJ23: =IF($AB23<$AR$5,$AC23>($AB23-$AR$33)/$AQ$33,FALSE) -> FALSE | AL23: =OR($AD23>$AQ$17,AND($AB23>$AR$16,$AD23>$AQ$16)) -> FALSE | AM23: =OR($AD23<$AQ$20,AND($AB23>$AR$16,$AD23<$AQ$21)) -> FALSE | AN23: =IF(OR(AL23:AM23),דלק!C20,"") | BA23: 100 | BB23: 20 | BH23: 3000 | BI23: 200
C24: 8 | D24: =IF(E24="","",ראשי!F31) | E24: =IFERROR(INDEX($E$40:$H$51,MATCH($C24,$I$40:$I$51,0),1),"") | F24: =IF(E24<>"",D24*E24,"") | G24: =IF(E24<>"",D24*H24,"") | H24: =IFERROR(INDEX($E$40:$H$51,MATCH($C24,$I$40:$I$51,0),4),"") | K24: =IF('משקל מערכות'!$B18=0,"",'משקל מערכות'!C18) -> WEIGHT ON HOOK | L24: =IF('משקל מערכות'!$B18=0,"",'משקל מערכות'!D18) -> 0 | M24: =IF('משקל מערכות'!$B18=0,"",'משקל מערכות'!E18) -> 4427 | N24: =IF('משקל מערכות'!$B18=0,"",'משקל מערכות'!F18) -> 0 | O24: =IF('משקל מערכות'!$B18=0,"",'משקל מערכות'!G18) -> 0 | P24: =IF('משקל מערכות'!$B18=0,"",'משקל מערכות'!H18) -> 0 | T24: =IF($T$5+דלק!$C21>takoffweight+1,takoffweight,$T$5+דלק!$C21) -> 2889.602 | U24: =IF($T$5+דלק!$C21>takoffweight+1,INDIRECT(ADDRESS(ROW()-1,COLUMN())),($T$5*$U$5+דלק!$C21*דלק!$D21)/($T$5+דלק!$C21)) -> 4462.2952 | V24: =IF($T$5+דלק!$C21>takoffweight,INDIRECT(ADDRESS(ROW()-1,COLUMN())),($T$5*$V$5+דלק!$C21*דלק!$E21)/($T$5+דלק!$C21)) -> -4.9042661 | X24: =IF($T24<$AR$5,$U24<($T24-$AR$32)/$AQ$32,FALSE) -> FALSE | Y24: =IF($T24<$AR$5,$U24>($T24-$AR$33)/$AQ$33,FALSE) -> FALSE | Z24: =IF($Y24,דלק!$C21,"") | AA24: 190 | AB24: =IF($AB$5+דלק!$C21>takoffweight+1,takoffweight,$AB$5+דלק!$C21) -> 2889.602 | AC24: =IF($AB$5+דלק!$C21>takoffweight+1,INDIRECT(ADDRESS(ROW()-1,COLUMN())),($AB$5*$AC$5+דלק!$C21*דלק!$D21)/($AB$5+דלק!$C21)) -> 4462.2952 | AD24: =IF($AB$5+דלק!$C21>takoffweight,INDIRECT(ADDRESS(ROW()-1,COLUMN())),($AB$5*$AD$5+דלק!$C21*דלק!$E21)/($AB$5+דלק!$C21)) -> -4.9042661 | AF24: =IF($AH24,דלק!$C21,"") | AG24: =IF($AI24,דלק!$C21,"") | AH24: =OR($AC24<($AB24-$AR$34)/$AQ$34,$AC24<4250) -> FALSE | AI24: =IF(AB24<takeoffWT2,IF($AB24<$AR$5,$AC24<($AB24-$AR$32)/$AQ$32,FALSE),FALSE) -> FALSE | AJ24: =IF($AB24<$AR$5,$AC24>($AB24-$AR$33)/$AQ$33,FALSE) -> FALSE | AL24: =OR($AD24>$AQ$17,AND($AB24>$AR$16,$AD24>$AQ$16)) -> FALSE | AM24: =OR($AD24<$AQ$20,AND($AB24>$AR$16,$AD24<$AQ$21)) -> FALSE | AN24: =IF(OR(AL24:AM24),דלק!C21,"") | BA24: 105 | BB24: 21 | BH24: 3050 | BI24: 150
C25: 9 | D25: =IF(E25="","",ראשי!D31) | E25: =IFERROR(INDEX($E$40:$H$51,MATCH($C25,$I$40:$I$51,0),1),"") | F25: =IF(E25<>"",D25*E25,"") | G25: =IF(E25<>"",D25*H25,"") | H25: =IFERROR(INDEX($E$40:$H$51,MATCH($C25,$I$40:$I$51,0),4),"") | K25: =IF('משקל מערכות'!$B19=0,"",'משקל מערכות'!C19) | L25: =IF('משקל מערכות'!$B19=0,"",'משקל מערכות'!D19) | M25: =IF('משקל מערכות'!$B19=0,"",'משקל מערכות'!E19) | N25: =IF('משקל מערכות'!$B19=0,"",'משקל מערכות'!F19) | O25: =IF('משקל מערכות'!$B19=0,"",'משקל מערכות'!G19) | P25: =IF('משקל מערכות'!$B19=0,"",'משקל מערכות'!H19) | T25: =IF($T$5+דלק!$C22>takoffweight+1,takoffweight,$T$5+דלק!$C22) -> 2899.602 | U25: =IF($T$5+דלק!$C22>takoffweight+1,INDIRECT(ADDRESS(ROW()-1,COLUMN())),($T$5*$U$5+דלק!$C22*דלק!$D22)/($T$5+דלק!$C22)) -> 4462.4736 | V25: =IF($T$5+דלק!$C22>takoffweight,INDIRECT(ADDRESS(ROW()-1,COLUMN())),($T$5*$V$5+דלק!$C22*דלק!$E22)/($T$5+דלק!$C22)) -> -4.8563138 | X25: =IF($T25<$AR$5,$U25<($T25-$AR$32)/$AQ$32,FALSE) -> FALSE | Y25: =IF($T25<$AR$5,$U25>($T25-$AR$33)/$AQ$33,FALSE) -> FALSE | Z25: =IF($Y25,דלק!$C22,"") | AA25: 200 | AB25: =IF($AB$5+דלק!$C22>takoffweight+1,takoffweight,$AB$5+דלק!$C22) -> 2899.602 | AC25: =IF($AB$5+דלק!$C22>takoffweight+1,INDIRECT(ADDRESS(ROW()-1,COLUMN())),($AB$5*$AC$5+דלק!$C22*דלק!$D22)/($AB$5+דלק!$C22)) -> 4462.4736 | AD25: =IF($AB$5+דלק!$C22>takoffweight,INDIRECT(ADDRESS(ROW()-1,COLUMN())),($AB$5*$AD$5+דלק!$C22*דלק!$E22)/($AB$5+דלק!$C22)) -> -4.8563138 | AF25: =IF($AH25,דלק!$C22,"") | AG25: =IF($AI25,דלק!$C22,"") | AH25: =OR($AC25<($AB25-$AR$34)/$AQ$34,$AC25<4250) -> FALSE | AI25: =IF(AB25<takeoffWT2,IF($AB25<$AR$5,$AC25<($AB25-$AR$32)/$AQ$32,FALSE),FALSE) -> FALSE | AJ25: =IF($AB25<$AR$5,$AC25>($AB25-$AR$33)/$AQ$33,FALSE) -> FALSE | AL25: =OR($AD25>$AQ$17,AND($AB25>$AR$16,$AD25>$AQ$16)) -> FALSE | AM25: =OR($AD25<$AQ$20,AND($AB25>$AR$16,$AD25<$AQ$21)) -> FALSE | AN25: =IF(OR(AL25:AM25),דלק!C22,"") | BA25: 110 | BB25: 22 | BH25: 3100 | BI25: 100
C26: 11 | D26: =IF(E26="","",INPUT11) | E26: =IFERROR(INDEX($E$40:$H$51,MATCH($C26,$I$40:$I$51,0),1),"") | F26: =IF(E26<>"",D26*E26,"") | G26: =IF(E26<>"",D26*H26,"") | H26: =IFERROR(INDEX($E$40:$H$51,MATCH($C26,$I$40:$I$51,0),4),"") | T26: =IF($T$5+דלק!$C23>takoffweight+1,takoffweight,$T$5+דלק!$C23) -> 2909.602 | U26: =IF($T$5+דלק!$C23>takoffweight+1,INDIRECT(ADDRESS(ROW()-1,COLUMN())),($T$5*$U$5+דלק!$C23*דלק!$D23)/($T$5+דלק!$C23)) -> 4462.661 | V26: =IF($T$5+דלק!$C23>takoffweight,INDIRECT(ADDRESS(ROW()-1,COLUMN())),($T$5*$V$5+דלק!$C23*דלק!$E23)/($T$5+דלק!$C23)) -> -4.8808659 | X26: =IF($T26<$AR$5,$U26<($T26-$AR$32)/$AQ$32,FALSE) -> FALSE | Y26: =IF($T26<$AR$5,$U26>($T26-$AR$33)/$AQ$33,FALSE) -> FALSE | Z26: =IF($Y26,דלק!$C23,"") | AA26: 210 | AB26: =IF($AB$5+דלק!$C23>takoffweight+1,takoffweight,$AB$5+דלק!$C23) -> 2909.602 | AC26: =IF($AB$5+דלק!$C23>takoffweight+1,INDIRECT(ADDRESS(ROW()-1,COLUMN())),($AB$5*$AC$5+דלק!$C23*דלק!$D23)/($AB$5+דלק!$C23)) -> 4462.661 | AD26: =IF($AB$5+דלק!$C23>takoffweight,INDIRECT(ADDRESS(ROW()-1,COLUMN())),($AB$5*$AD$5+דלק!$C23*דלק!$E23)/($AB$5+דלק!$C23)) -> -4.8808659 | AF26: =IF($AH26,דלק!$C23,"") | AG26: =IF($AI26,דלק!$C23,"") | AH26: =OR($AC26<($AB26-$AR$34)/$AQ$34,$AC26<4250) -> FALSE | AI26: =IF(AB26<takeoffWT2,IF($AB26<$AR$5,$AC26<($AB26-$AR$32)/$AQ$32,FALSE),FALSE) -> FALSE | AJ26: =IF($AB26<$AR$5,$AC26>($AB26-$AR$33)/$AQ$33,FALSE) -> FALSE | AL26: =OR($AD26>$AQ$17,AND($AB26>$AR$16,$AD26>$AQ$16)) -> FALSE | AM26: =OR($AD26<$AQ$20,AND($AB26>$AR$16,$AD26<$AQ$21)) -> FALSE | AN26: =IF(OR(AL26:AM26),דלק!C23,"") | AQ26: חישוב מרכז כובד רוחבי | BA26: 115 | BB26: 23 | BH26: 3150 | BI26: 50
C27: 12 | D27: =IF(E27="","",INPUT12) | E27: =IFERROR(INDEX($E$40:$H$51,MATCH($C27,$I$40:$I$51,0),1),"") | F27: =IF(E27<>"",D27*E27,"") | G27: =IF(E27<>"",D27*H27,"") | H27: =IFERROR(INDEX($E$40:$H$51,MATCH($C27,$I$40:$I$51,0),4),"") | T27: =IF($T$5+דלק!$C24>takoffweight+1,takoffweight,$T$5+דלק!$C24) -> 2919.602 | U27: =IF($T$5+דלק!$C24>takoffweight+1,INDIRECT(ADDRESS(ROW()-1,COLUMN())),($T$5*$U$5+דלק!$C24*דלק!$D24)/($T$5+דלק!$C24)) -> 4462.8265 | V27: =IF($T$5+דלק!$C24>takoffweight,INDIRECT(ADDRESS(ROW()-1,COLUMN())),($T$5*$V$5+דלק!$C24*דלק!$E24)/($T$5+דלק!$C24)) -> -4.8367473 | X27: =IF($T27<$AR$5,$U27<($T27-$AR$32)/$AQ$32,FALSE) -> FALSE | Y27: =IF($T27<$AR$5,$U27>($T27-$AR$33)/$AQ$33,FALSE) -> FALSE | Z27: =IF($Y27,דלק!$C24,"") | AA27: 220 | AB27: =IF($AB$5+דלק!$C24>takoffweight+1,takoffweight,$AB$5+דלק!$C24) -> 2919.602 | AC27: =IF($AB$5+דלק!$C24>takoffweight+1,INDIRECT(ADDRESS(ROW()-1,COLUMN())),($AB$5*$AC$5+דלק!$C24*דלק!$D24)/($AB$5+דלק!$C24)) -> 4462.8265 | AD27: =IF($AB$5+דלק!$C24>takoffweight,INDIRECT(ADDRESS(ROW()-1,COLUMN())),($AB$5*$AD$5+דלק!$C24*דלק!$E24)/($AB$5+דלק!$C24)) -> -4.8367473 | AF27: =IF($AH27,דלק!$C24,"") | AG27: =IF($AI27,דלק!$C24,"") | AH27: =OR($AC27<($AB27-$AR$34)/$AQ$34,$AC27<4250) -> FALSE | AI27: =IF(AB27<takeoffWT2,IF($AB27<$AR$5,$AC27<($AB27-$AR$32)/$AQ$32,FALSE),FALSE) -> FALSE | AJ27: =IF($AB27<$AR$5,$AC27>($AB27-$AR$33)/$AQ$33,FALSE) -> FALSE | AL27: =OR($AD27>$AQ$17,AND($AB27>$AR$16,$AD27>$AQ$16)) -> FALSE | AM27: =OR($AD27<$AQ$20,AND($AB27>$AR$16,$AD27<$AQ$21)) -> FALSE | AN27: =IF(OR(AL27:AM27),דלק!C24,"") | AQ27: =T5 -> 2699.602 | AR27: =MIN($V$5:$V$76) -> -5.8828587 | BA27: 120 | BB27: 24 | BH27: 3200 | BI27: 0
C28: 13 | D28: =IF(E28="","",INPUT13) | E28: =IFERROR(INDEX($E$40:$H$51,MATCH($C28,$I$40:$I$51,0),1),"") | F28: =IF(E28<>"",D28*E28,"") | G28: =IF(E28<>"",D28*H28,"") | H28: =IFERROR(INDEX($E$40:$H$51,MATCH($C28,$I$40:$I$51,0),4),"") | K28: MANUALLY ADDED EQUIPMENT | T28: =IF($T$5+דלק!$C25>takoffweight+1,takoffweight,$T$5+דלק!$C25) -> 2929.602 | U28: =IF($T$5+דלק!$C25>takoffweight+1,INDIRECT(ADDRESS(ROW()-1,COLUMN())),($T$5*$U$5+דלק!$C25*דלק!$D25)/($T$5+דלק!$C25)) -> 4465.295 | V28: =IF($T$5+דלק!$C25>takoffweight,INDIRECT(ADDRESS(ROW()-1,COLUMN())),($T$5*$V$5+דלק!$C25*דלק!$E25)/($T$5+דלק!$C25)) -> -4.8714389 | X28: =IF($T28<$AR$5,$U28<($T28-$AR$32)/$AQ$32,FALSE) -> FALSE | Y28: =IF($T28<$AR$5,$U28>($T28-$AR$33)/$AQ$33,FALSE) -> FALSE | Z28: =IF($Y28,דלק!$C25,"") | AA28: 230 | AB28: =IF($AB$5+דלק!$C25>takoffweight+1,takoffweight,$AB$5+דלק!$C25) -> 2929.602 | AC28: =IF($AB$5+דלק!$C25>takoffweight+1,INDIRECT(ADDRESS(ROW()-1,COLUMN())),($AB$5*$AC$5+דלק!$C25*דלק!$D25)/($AB$5+דלק!$C25)) -> 4465.295 | AD28: =IF($AB$5+דלק!$C25>takoffweight,INDIRECT(ADDRESS(ROW()-1,COLUMN())),($AB$5*$AD$5+דלק!$C25*דלק!$E25)/($AB$5+דלק!$C25)) -> -4.8714389 | AF28: =IF($AH28,דלק!$C25,"") | AG28: =IF($AI28,דלק!$C25,"") | AH28: =OR($AC28<($AB28-$AR$34)/$AQ$34,$AC28<4250) -> FALSE | AI28: =IF(AB28<takeoffWT2,IF($AB28<$AR$5,$AC28<($AB28-$AR$32)/$AQ$32,FALSE),FALSE) -> FALSE | AJ28: =IF($AB28<$AR$5,$AC28>($AB28-$AR$33)/$AQ$33,FALSE) -> FALSE | AL28: =OR($AD28>$AQ$17,AND($AB28>$AR$16,$AD28>$AQ$16)) -> FALSE | AM28: =OR($AD28<$AQ$20,AND($AB28>$AR$16,$AD28<$AQ$21)) -> FALSE | AN28: =IF(OR(AL28:AM28),דלק!C25,"") | AQ28: =T76 -> 3200 | AR28: =MAX($V$5:$V$76) -> -4.6023559 | BA28: 125 | BB28: 25 | BH28: 3250 | BI28: -50
C29: 14 | D29: =IF(E29="","",INPUT14) | E29: =IFERROR(INDEX($E$40:$H$51,MATCH($C29,$I$40:$I$51,0),1),"") | F29: =IF(E29<>"",D29*E29,"") | G29: =IF(E29<>"",D29*H29,"") | H29: =IFERROR(INDEX($E$40:$H$51,MATCH($C29,$I$40:$I$51,0),4),"") | K29: ציוד | L29: משקל | M29: LONG1 ARM | N29: מומנט אורכי | O29: LONG2 ARM | P29: מומנט אורכי2 | Q29: מומנט רוחבי | R29: LAT ARM | T29: =IF($T$5+דלק!$C26>takoffweight+1,takoffweight,$T$5+דלק!$C26) -> 2939.602 | U29: =IF($T$5+דלק!$C26>takoffweight+1,INDIRECT(ADDRESS(ROW()-1,COLUMN())),($T$5*$U$5+דלק!$C26*דלק!$D26)/($T$5+דלק!$C26)) -> 4468.1958 | V29: =IF($T$5+דלק!$C26>takoffweight,INDIRECT(ADDRESS(ROW()-1,COLUMN())),($T$5*$V$5+דלק!$C26*דלק!$E26)/($T$5+דלק!$C26)) -> -4.8310544 | X29: =IF($T29<$AR$5,$U29<($T29-$AR$32)/$AQ$32,FALSE) -> FALSE | Y29: =IF($T29<$AR$5,$U29>($T29-$AR$33)/$AQ$33,FALSE) -> FALSE | Z29: =IF($Y29,דלק!$C26,"") | AA29: 240 | AB29: =IF($AB$5+דלק!$C26>takoffweight+1,takoffweight,$AB$5+דלק!$C26) -> 2939.602 | AC29: =IF($AB$5+דלק!$C26>takoffweight+1,INDIRECT(ADDRESS(ROW()-1,COLUMN())),($AB$5*$AC$5+דלק!$C26*דלק!$D26)/($AB$5+דלק!$C26)) -> 4468.1958 | AD29: =IF($AB$5+דלק!$C26>takoffweight,INDIRECT(ADDRESS(ROW()-1,COLUMN())),($AB$5*$AD$5+דלק!$C26*דלק!$E26)/($AB$5+דלק!$C26)) -> -4.8310544 | AF29: =IF($AH29,דלק!$C26,"") | AG29: =IF($AI29,דלק!$C26,"") | AH29: =OR($AC29<($AB29-$AR$34)/$AQ$34,$AC29<4250) -> FALSE | AI29: =IF(AB29<takeoffWT2,IF($AB29<$AR$5,$AC29<($AB29-$AR$32)/$AQ$32,FALSE),FALSE) -> FALSE | AJ29: =IF($AB29<$AR$5,$AC29>($AB29-$AR$33)/$AQ$33,FALSE) -> FALSE | AL29: =OR($AD29>$AQ$17,AND($AB29>$AR$16,$AD29>$AQ$16)) -> FALSE | AM29: =OR($AD29<$AQ$20,AND($AB29>$AR$16,$AD29<$AQ$21)) -> FALSE | AN29: =IF(OR(AL29:AM29),דלק!C26,"") | BA29: 130 | BB29: 26 | BH29: 3300 | BI29: -100
C30: 15 | D30: =IF(E30="","",INPUT15) | E30: =IFERROR(INDEX($E$40:$H$51,MATCH($C30,$I$40:$I$51,0),1),"") | F30: =IF(E30<>"",D30*E30,"") | G30: =IF(E30<>"",D30*H30,"") | H30: =IFERROR(INDEX($E$40:$H$51,MATCH($C30,$I$40:$I$51,0),4),"") | K30: פריסטים קבועים | L30: =IF(M30="","",ראשי!D34) | M30: =IF(ראשי!$F34="","",VLOOKUP(ראשי!$F34,LONG_LOADING_TABLE,2,FALSE)) | N30: =IF(M30<>"",L30*M30,"") | O30: =IF(ראשי!$F34="","",VLOOKUP(ראשי!$F34,LONG_LOADING_TABLE,3,FALSE)) | P30: =IF(O30<>"",L30*O30,"") | Q30: =IF(R30<>"",L30*R30,"") | R30: =IF(ראשי!$H34="","",VLOOKUP(ראשי!$H34,LAT_LOADING_TABLE,2,FALSE)) | T30: =IF($T$5+דלק!$C27>takoffweight+1,takoffweight,$T$5+דלק!$C27) -> 2949.602 | U30: =IF($T$5+דלק!$C27>takoffweight+1,INDIRECT(ADDRESS(ROW()-1,COLUMN())),($T$5*$U$5+דלק!$C27*דלק!$D27)/($T$5+דלק!$C27)) -> 4471.1108 | V30: =IF($T$5+דלק!$C27>takoffweight,INDIRECT(ADDRESS(ROW()-1,COLUMN())),($T$5*$V$5+דלק!$C27*דלק!$E27)/($T$5+דלק!$C27)) -> -4.7909437 | X30: =IF($T30<$AR$5,$U30<($T30-$AR$32)/$AQ$32,FALSE) -> FALSE | Y30: =IF($T30<$AR$5,$U30>($T30-$AR$33)/$AQ$33,FALSE) -> FALSE | Z30: =IF($Y30,דלק!$C27,"") | AA30: 250 | AB30: =IF($AB$5+דלק!$C27>takoffweight+1,takoffweight,$AB$5+דלק!$C27) -> 2949.602 | AC30: =IF($AB$5+דלק!$C27>takoffweight+1,INDIRECT(ADDRESS(ROW()-1,COLUMN())),($AB$5*$AC$5+דלק!$C27*דלק!$D27)/($AB$5+דלק!$C27)) -> 4471.1108 | AD30: =IF($AB$5+דלק!$C27>takoffweight,INDIRECT(ADDRESS(ROW()-1,COLUMN())),($AB$5*$AD$5+דלק!$C27*דלק!$E27)/($AB$5+דלק!$C27)) -> -4.7909437 | AF30: =IF($AH30,דלק!$C27,"") | AG30: =IF($AI30,דלק!$C27,"") | AH30: =OR($AC30<($AB30-$AR$34)/$AQ$34,$AC30<4250) -> FALSE | AI30: =IF(AB30<takeoffWT2,IF($AB30<$AR$5,$AC30<($AB30-$AR$32)/$AQ$32,FALSE),FALSE) -> FALSE | AJ30: =IF($AB30<$AR$5,$AC30>($AB30-$AR$33)/$AQ$33,FALSE) -> FALSE | AL30: =OR($AD30>$AQ$17,AND($AB30>$AR$16,$AD30>$AQ$16)) -> FALSE | AM30: =OR($AD30<$AQ$20,AND($AB30>$AR$16,$AD30<$AQ$21)) -> FALSE | AN30: =IF(OR(AL30:AM30),דלק!C27,"") | AP30: CG LIMIT GRAPH | BA30: 135 | BB30: 27 | BH30: 3350 | BI30: -150
C31: 21 | D31: =IF(E31="","",INPUT21) | E31: =IFERROR(INDEX($E$40:$H$51,MATCH($C31,$I$40:$I$51,0),1),"") | F31: =IF(E31<>"",D31*E31,"") | G31: =IF(E31<>"",D31*H31,"") | H31: =IFERROR(INDEX($E$40:$H$51,MATCH($C31,$I$40:$I$51,0),4),"") | L31: =IF(M31="","",ראשי!D35) | M31: =IF(ראשי!$F35="","",VLOOKUP(ראשי!$F35,LONG_LOADING_TABLE,2,FALSE)) | N31: =IF(M31<>"",L31*M31,"") | O31: =IF(ראשי!$F35="","",VLOOKUP(ראשי!$F35,LONG_LOADING_TABLE,3,FALSE)) | P31: =IF(O31<>"",L31*O31,"") | Q31: =IF(R31<>"",L31*R31,"") | R31: =IF(ראשי!$H35="","",VLOOKUP(ראשי!$H35,LAT_LOADING_TABLE,2,FALSE)) | T31: =IF($T$5+דלק!$C28>takoffweight+1,takoffweight,$T$5+דלק!$C28) -> 2959.602 | U31: =IF($T$5+דלק!$C28>takoffweight+1,INDIRECT(ADDRESS(ROW()-1,COLUMN())),($T$5*$U$5+דלק!$C28*דלק!$D28)/($T$5+דלק!$C28)) -> 4473.7357 | V31: =IF($T$5+דלק!$C28>takoffweight,INDIRECT(ADDRESS(ROW()-1,COLUMN())),($T$5*$V$5+דלק!$C28*דלק!$E28)/($T$5+דלק!$C28)) -> -4.7511041 | X31: =IF($T31<$AR$5,$U31<($T31-$AR$32)/$AQ$32,FALSE) -> FALSE | Y31: =IF($T31<$AR$5,$U31>($T31-$AR$33)/$AQ$33,FALSE) -> FALSE | Z31: =IF($Y31,דלק!$C28,"") | AA31: 260 | AB31: =IF($AB$5+דלק!$C28>takoffweight+1,takoffweight,$AB$5+דלק!$C28) -> 2959.602 | AC31: =IF($AB$5+דלק!$C28>takoffweight+1,INDIRECT(ADDRESS(ROW()-1,COLUMN())),($AB$5*$AC$5+דלק!$C28*דלק!$D28)/($AB$5+דלק!$C28)) -> 4473.7357 | AD31: =IF($AB$5+דלק!$C28>takoffweight,INDIRECT(ADDRESS(ROW()-1,COLUMN())),($AB$5*$AD$5+דלק!$C28*דלק!$E28)/($AB$5+דלק!$C28)) -> -4.7511041 | AF31: =IF($AH31,דלק!$C28,"") | AG31: =IF($AI31,דלק!$C28,"") | AH31: =OR($AC31<($AB31-$AR$34)/$AQ$34,$AC31<4250) -> FALSE | AI31: =IF(AB31<takeoffWT2,IF($AB31<$AR$5,$AC31<($AB31-$AR$32)/$AQ$32,FALSE),FALSE) -> FALSE | AJ31: =IF($AB31<$AR$5,$AC31>($AB31-$AR$33)/$AQ$33,FALSE) -> FALSE | AL31: =OR($AD31>$AQ$17,AND($AB31>$AR$16,$AD31>$AQ$16)) -> FALSE | AM31: =OR($AD31<$AQ$20,AND($AB31>$AR$16,$AD31<$AQ$21)) -> FALSE | AN31: =IF(OR(AL31:AM31),דלק!C28,"") | AQ31: a | AR31: b | BA31: 140 | BB31: 28 | BH31: 3400 | BI31: -200
C32: 22 | D32: =IF(E32="","",INPUT22) | E32: =IFERROR(INDEX($E$40:$H$51,MATCH($C32,$I$40:$I$51,0),1),"") | F32: =IF(E32<>"",D32*E32,"") | G32: =IF(E32<>"",D32*H32,"") | H32: =IFERROR(INDEX($E$40:$H$51,MATCH($C32,$I$40:$I$51,0),4),"") | L32: =IF(M32="","",ראשי!D36) | M32: =IF(ראשי!$F36="","",VLOOKUP(ראשי!$F36,LONG_LOADING_TABLE,2,FALSE)) | N32: =IF(M32<>"",L32*M32,"") | O32: =IF(ראשי!$F36="","",VLOOKUP(ראשי!$F36,LONG_LOADING_TABLE,3,FALSE)) | P32: =IF(O32<>"",L32*O32,"") | Q32: =IF(R32<>"",L32*R32,"") | R32: =IF(ראשי!$H36="","",VLOOKUP(ראשי!$H36,LAT_LOADING_TABLE,2,FALSE)) | T32: =IF($T$5+דלק!$C29>takoffweight+1,takoffweight,$T$5+דלק!$C29) -> 2969.602 | U32: =IF($T$5+דלק!$C29>takoffweight+1,INDIRECT(ADDRESS(ROW()-1,COLUMN())),($T$5*$U$5+דלק!$C29*דלק!$D29)/($T$5+דלק!$C29)) -> 4474.9119 | V32: =IF($T$5+דלק!$C29>takoffweight,INDIRECT(ADDRESS(ROW()-1,COLUMN())),($T$5*$V$5+דלק!$C29*דלק!$E29)/($T$5+דלק!$C29)) -> -4.8024541 | X32: =IF($T32<$AR$5,$U32<($T32-$AR$32)/$AQ$32,FALSE) -> FALSE | Y32: =IF($T32<$AR$5,$U32>($T32-$AR$33)/$AQ$33,FALSE) -> FALSE | Z32: =IF($Y32,דלק!$C29,"") | AA32: 270 | AB32: =IF($AB$5+דלק!$C29>takoffweight+1,takoffweight,$AB$5+דלק!$C29) -> 2969.602 | AC32: =IF($AB$5+דלק!$C29>takoffweight+1,INDIRECT(ADDRESS(ROW()-1,COLUMN())),($AB$5*$AC$5+דלק!$C29*דלק!$D29)/($AB$5+דלק!$C29)) -> 4474.9119 | AD32: =IF($AB$5+דלק!$C29>takoffweight,INDIRECT(ADDRESS(ROW()-1,COLUMN())),($AB$5*$AD$5+דלק!$C29*דלק!$E29)/($AB$5+דלק!$C29)) -> -4.8024541 | AF32: =IF($AH32,דלק!$C29,"") | AG32: =IF($AI32,דלק!$C29,"") | AH32: =OR($AC32<($AB32-$AR$34)/$AQ$34,$AC32<4250) -> FALSE | AI32: =IF(AB32<takeoffWT2,IF($AB32<$AR$5,$AC32<($AB32-$AR$32)/$AQ$32,FALSE),FALSE) -> FALSE | AJ32: =IF($AB32<$AR$5,$AC32>($AB32-$AR$33)/$AQ$33,FALSE) -> FALSE | AL32: =OR($AD32>$AQ$17,AND($AB32>$AR$16,$AD32>$AQ$16)) -> FALSE | AM32: =OR($AD32<$AQ$20,AND($AB32>$AR$16,$AD32<$AQ$21)) -> FALSE | AN32: =IF(OR(AL32:AM32),דלק!C29,"") | AP32: FWD | AQ32: =SLOPE(נתונים!AR8:AR9,נתונים!AQ8:AQ9) -> 39.393939 | AR32: =AR8-AQ8*AQ32 -> -168845.45 | BA32: 145 | BB32: 29 | BH32: 3450 | BI32: -250
